Workbook

Sheet Ctrl
B3: Project Eagle
B4: Model Control | G4: Runway | H4: Fundraise | I4: Fund. Date | J4: End. ARR | K4: Deferred Rev.
B5: ="CASE "&$H$11&": "&H12 -> CASE 1: BASE CASE | G5: =Sum!$E$19 -> 16 | H5: =Sum!$E$28 -> 3259.9201 | I5: =Sum!$E$21 -> 45626 | J5: ='Calc.Mth'!$AI$57 -> 2999.7355 | K5: =Fin.Mth!$AI$81 -> 1487.7626
I10: KEY SCENARIOS | P10: SENSITIVITIES
H11: 1 | I11: 1 | J11: =I11+1 -> 2 | K11: =J11+1 -> 3 | L11: =K11+1 -> 4 | M11: =L11+1 -> 5 | N11: =M11+1 -> 6 | O11: =N11+1 -> 7 | P11: =O11+1 -> 8 | Q11: =P11+1 -> 9 | ... W11: =V11+1 -> 15
B12: SCENARIO SELECTOR>> | H12: =OFFSET(H12,,H11) -> BASE CASE | I12: BASE CASE | J12: DISC. CASE | K12: LOWER CHURN (MTHLY) | L12: LOWER CHURN (ANN) | M12: PRICE ESCALATION | N12: UPSELL | O12: LOWER CHURN + UPSELL | P12: +10% LAUNCH VOLUME | Q12: -10% LAUNCH VOLUME | R12: -10% CHURN | S12: +10% CHURN | T12: +10% MoM GROWTH | U12: -10% MoM GROWTH | V12: +10% PRICING | W12: -10% PRICING
N14: 1
A15: X | B15: OUTPUTS
B17: Fundraising Size | F17: $K | H17: =H5 -> 3259.9201 | I17: 3259.9201 | J17: 4893.9226 | K17: 3516.2757 | L17: 3555.9476 | M17: 3168.3163 | N17: 3167.8482 | O17: 3258.6784 | P17: 3225.5844 | Q17: 3134.2058 | R17: 3555.9476 | S17: 3199.723 | T17: 3330.8753 | U17: 3254.7806 | V17: 2858.7619 | W17: 3763.2283
B18: Fundraising Date | F18: date | H18: =Sum!E21 -> 45626 | I18: 45626 | J18: 45504 | K18: 45626 | L18: 45626 | M18: 45626 | N18: 45657 | O18: 45626 | P18: 45626 | Q18: 45657 | R18: 45626 | S18: 45657 | T18: 45626 | U18: 45626 | V18: 45688 | W18: 45596
B19: Runway | F19: months | H19: =G5 -> 16 | I19: 16 | J19: 12 | K19: 16 | L19: 16 | M19: 16 | N19: 17 | O19: 16 | P19: 16 | Q19: 17 | R19: 16 | S19: 17 | T19: 16 | U19: 16 | V19: 18 | W19: 15
B20: Ending ARR | F20: $K | H20: =J5 -> 2999.7355 | I20: 2999.7355 | J20: 3568.1302 | K20: 3459.7404 | L20: 3647.4052 | M20: 3101.0088 | N20: 3762.9422 | O20: 4262.16 | P20: 3299.7091 | Q20: 2699.762 | R20: 3647.4052 | S20: 2770.2446 | T20: 3673.9487 | U20: 2423.4551 | V20: 3299.7091 | W20: 2699.762
A22: X | B22: FUNDRAISING ASSUMPTIONS
B24: Minimum Cash | F24: $K | H24: =OFFSET(H24,,H$11) -> 1500 | I24: 1500 | J24: =$I24 -> 1500 | K24: =$I24 -> 1500 | L24: =$I24 -> 1500 | M24: =$I24 -> 1500 | N24: =$I24 -> 1500 | O24: =$I24 -> 1500 | P24: =$I24 -> 1500 | Q24: =$I24 -> 1500 | ... W24: =$I24 -> 1500
B25: Runway Trigger Prior to Fundraise | F25: months | H25: =OFFSET(H25,,H$11) -> 6 | I25: 6 | J25: =$I25 -> 6 | K25: =$I25 -> 6 | L25: =$I25 -> 6 | M25: =$I25 -> 6 | N25: =$I25 -> 6 | O25: =$I25 -> 6 | P25: =$I25 -> 6 | Q25: =$I25 -> 6 | ... W25: =$I25 -> 6
B26: Growth Runway Post-Fundraise | F26: months | H26: =OFFSET(H26,,H$11) -> 0 | I26: 0 | J26: =$I26 -> 0 | K26: =$I26 -> 0 | L26: =$I26 -> 0 | M26: =$I26 -> 0 | N26: =$I26 -> 0 | O26: =$I26 -> 0 | P26: =$I26 -> 0 | Q26: =$I26 -> 0 | ... W26: =$I26 -> 0
A28: X | B28: VOLUME & PRICING ASSUMPTIONS
B30: Launch Profile
B31: Gross Adds Post-Launch Period | F31: # | H31: =OFFSET(H31,,H$11) -> 9830 | I31: 9830 | J31: =$I31 -> 9830 | K31: =$I31 -> 9830 | L31: =$I31 -> 9830 | M31: =$I31 -> 9830 | N31: =$I31 -> 9830 | O31: =$I31 -> 9830 | P31: =$I31*(1+0.1) -> 10813 | Q31: =$I31*(1-0.1) -> 8847 | R31: =$I31 -> 9830 | S31: =$I31 -> 9830 | T31: =$I31 -> 9830 | U31: =$I31 -> 9830 | V31: =$I31 -> 9830 | W31: =$I31 -> 9830 | X31: << required # of customers post-launch to reach $3m ARR
B33: Ramp-up Profile
B34: Month 1 | F34: % | H34: =OFFSET(H34,,H$11) -> 0.5 | I34: 0.5 | J34: =$I34 -> 0.5 | K34: =$I34 -> 0.5 | L34: =$I34 -> 0.5 | M34: =$I34 -> 0.5 | N34: =$I34 -> 0.5 | O34: =$I34 -> 0.5 | P34: =$I34 -> 0.5 | Q34: =$I34 -> 0.5 | ... W34: =$I34 -> 0.5
B35: Month 2 | F35: % | H35: =OFFSET(H35,,H$11) -> 0.3 | I35: 0.3 | J35: =$I35 -> 0.3 | K35: =$I35 -> 0.3 | L35: =$I35 -> 0.3 | M35: =$I35 -> 0.3 | N35: =$I35 -> 0.3 | O35: =$I35 -> 0.3 | P35: =$I35 -> 0.3 | Q35: =$I35 -> 0.3 | ... W35: =$I35 -> 0.3
B36: Month 3 | F36: % | H36: =OFFSET(H36,,H$11) -> 0.2 | I36: 0.2 | J36: =$I36 -> 0.2 | K36: =$I36 -> 0.2 | L36: =$I36 -> 0.2 | M36: =$I36 -> 0.2 | N36: =$I36 -> 0.2 | O36: =$I36 -> 0.2 | P36: =$I36 -> 0.2 | Q36: =$I36 -> 0.2 | ... W36: =$I36 -> 0.2
B38: MoM Growth (%)
B39: Monthly Plan | F39: % | H39: =OFFSET(H39,,H$11) -> 0.1 | I39: 0.1 | J39: =I39*(1+0.2) -> 0.12 | K39: =$I39 -> 0.1 | L39: =$I39 -> 0.1 | M39: =$I39 -> 0.1 | N39: =$I39 -> 0.1 | O39: =$I39 -> 0.1 | P39: =$I39 -> 0.1 | Q39: =$I39 -> 0.1 | R39: =$I39 -> 0.1 | S39: =$I39 -> 0.1 | T39: =$I39*(1+0.1) -> 0.11 | U39: =$I39*(1-0.1) -> 0.09 | V39: =$I39 -> 0.1 | W39: =$I39 -> 0.1
B40: Annual Plan | F40: % | H40: =OFFSET(H40,,H$11) -> 0.07 | I40: 0.07 | J40: =I40*(1+0.2) -> 0.084 | K40: =$I40 -> 0.07 | L40: =$I40 -> 0.07 | M40: =$I40 -> 0.07 | N40: =I40*(1+0.1) -> 0.077 | O40: =N40 -> 0.077 | P40: =$I40 -> 0.07 | Q40: =$I40 -> 0.07 | R40: =$I40 -> 0.07 | S40: =$I40 -> 0.07 | T40: =$I40*(1+0.1) -> 0.077 | U40: =$I40*(1-0.1) -> 0.063 | V40: =$I40 -> 0.07 | W40: =$I40 -> 0.07
B42: Churn (%)
B43: =$B$39 -> Monthly Plan | F43: % | H43: =OFFSET(H43,,H$11) -> 0.25 | I43: 0.25 | J43: =$I43 -> 0.25 | K43: 0.15 | L43: 0.15 | M43: =$I43 -> 0.25 | N43: =I43*(1+0.1) -> 0.275 | O43: =N43-10% -> 0.175 | P43: =$I43 -> 0.25 | Q43: =$I43 -> 0.25 | R43: =$I43-10% -> 0.15 | S43: =$I43+10% -> 0.35 | T43: =$I43 -> 0.25 | U43: =$I43 -> 0.25 | V43: =$I43 -> 0.25 | W43: =$I43 -> 0.25
B44: =$B$40 -> Annual Plan | F44: % | H44: =OFFSET(H44,,H$11) -> 0.35 | I44: 0.35 | J44: =$I44 -> 0.35 | K44: 0.35 | L44: 0.25 | M44: =$I44 -> 0.35 | N44: 0.35 | O44: =N44-10% -> 0.25 | P44: =$I44 -> 0.35 | Q44: =$I44 -> 0.35 | R44: =$I44-10% -> 0.25 | S44: =$I44+10% -> 0.45 | T44: =$I44 -> 0.35 | U44: =$I44 -> 0.35 | V44: =$I44 -> 0.35 | W44: =$I44 -> 0.35
B46: Pricing
B47: =$B$39 -> Monthly Plan | F47: $ | H47: =OFFSET(H47,,H$11) -> 30 | I47: 30 | J47: =I47*(1-0.2) -> 24 | K47: =$I47 -> 30 | L47: =$I47 -> 30 | M47: =$I47 -> 30 | N47: =$I47 -> 30 | O47: =$I47 -> 30 | P47: =$I47 -> 30 | Q47: =$I47 -> 30 | R47: =$I47 -> 30 | ... U47: =$I47 -> 30 | V47: =$I47*(1+0.1) -> 33 | W47: =$I47*(1-0.1) -> 27
B48: =$B$40 -> Annual Plan | F48: $ | H48: =OFFSET(H48,,H$11) -> 330 | I48: 330 | J48: =I48*(1-0.2) -> 264 | K48: =$I48 -> 330 | L48: =$I48 -> 330 | M48: =$I48 -> 330 | N48: =$I48 -> 330 | O48: =$I48 -> 330 | P48: =$I48 -> 330 | Q48: =$I48 -> 330 | R48: =$I48 -> 330 | ... U48: =$I48 -> 330 | V48: =$I48*(1+0.1) -> 363 | W48: =$I48*(1-0.1) -> 297
B50: % growth YoY
B51: =$B$39 -> Monthly Plan | F51: % | H51: =OFFSET(H51,,H$11) -> 0 | I51: 0 | J51: =$I51 -> 0 | K51: =$I51 -> 0 | L51: =$I51 -> 0 | M51: 0.03 | N51: 0.03 | O51: =N51 -> 0.03 | P51: =$I51 -> 0 | Q51: =$I51 -> 0 | R51: =$I51 -> 0 | S51: =$I51 -> 0 | T51: =$I51 -> 0 | U51: =$I51 -> 0 | V51: =$I51 -> 0 | W51: =$I51 -> 0
B52: =$B$40 -> Annual Plan | F52: % | H52: =OFFSET(H52,,H$11) -> 0 | I52: 0 | J52: =$I52 -> 0 | K52: =$I52 -> 0 | L52: =$I52 -> 0 | M52: 0.03 | N52: 0.03 | O52: =N52 -> 0.03 | P52: =$I52 -> 0 | Q52: =$I52 -> 0 | R52: =$I52 -> 0 | S52: =$I52 -> 0 | T52: =$I52 -> 0 | U52: =$I52 -> 0 | V52: =$I52 -> 0 | W52: =$I52 -> 0
A54: X | B54: MILESTONE ASSUMPTIONS
B56: ARR Milestone | F56: # | H56: =OFFSET(H56,,H$11) -> 750 | I56: 750 | J56: =$I56 -> 750 | K56: =$I56 -> 750 | L56: =$I56 -> 750 | M56: =$I56 -> 750 | N56: =$I56 -> 750 | O56: =$I56 -> 750 | P56: =$I56 -> 750 | Q56: =$I56 -> 750 | ... W56: =$I56 -> 750
B57: Customer Milestone | F57: # | H57: =OFFSET(H57,,H$11) -> 2500 | I57: 2500 | J57: =$I57 -> 2500 | K57: =$I57 -> 2500 | L57: =$I57 -> 2500 | M57: =$I57 -> 2500 | N57: =$I57 -> 2500 | O57: =$I57 -> 2500 | P57: =$I57 -> 2500 | Q57: =$I57 -> 2500 | ... W57: =$I57 -> 2500
B58: Headcount Milestone | F58: # | H58: =OFFSET(H58,,H$11) -> 20 | I58: 20 | J58: =$I58 -> 20 | K58: =$I58 -> 20 | L58: =$I58 -> 20 | M58: =$I58 -> 20 | N58: =$I58 -> 20 | O58: =$I58 -> 20 | P58: =$I58 -> 20 | Q58: =$I58 -> 20 | ... W58: =$I58 -> 20
A60: X | B60: HEADCOUNT ASSUMPTIONS
...

Sheet Sum
B3: Project Eagle
B4: Model Summary | G4: Runway | H4: Fundraise | I4: Fund. Date | J4: End. ARR | K4: Deferred Rev.
B5: =Ctrl!$B$5 -> CASE 1: BASE CASE | G5: =Sum!$E$19 -> 16 | H5: =Sum!$E$28 -> 3259.9201 | I5: =Sum!$E$21 -> 45626 | J5: ='Calc.Mth'!$AI$57 -> 2999.7355 | K5: =Fin.Mth!$AI$81 -> 1487.7626
A10: 1 | B10: DASHBOARD | W10: 2 | X10: CHARTS
K12: Quarterly | T12: Annual | X12: Customers (Monthly vs. Annual) & Pricing | AE12: Bookings, Revenue and ARR | AL12: Upsell | AN12: Base | AO12: Inc | AP12: End | AQ12: ARR
G13: $K, Dec Y/E | K13: =Fin.Qtr!L7 -> 45382 | L13: =Fin.Qtr!M7 -> 45473 | M13: =Fin.Qtr!N7 -> 45565 | N13: =Fin.Qtr!O7 -> 45657 | O13: =Fin.Qtr!P7 -> 45747 | P13: =Fin.Qtr!Q7 -> 45838 | Q13: =Fin.Qtr!R7 -> 45930 | R13: =Fin.Qtr!S7 -> 46022 | T13: =Fin.Qtr!U7 -> 45657 | U13: =Fin.Qtr!V7 -> 46022 | AL13: Base Case ARR | AP13: =AQ13 -> 2999.7355 | AQ13: 2999.7355
B14: FUNDRAISING SUMMARY | G14: OPERATING METRICS | AL14: Add: ARR from Price Escalation | AN14: =AP13 -> 2999.7355 | AO14: =AQ14-AP13 -> 101.27332 | AQ14: =Ctrl!M20 -> 3101.0088
B15: Model Date | E15: 45292 | G15: =Fin.Qtr!B17 -> # CUSTOMERS | AL15: Add: ARR from Upsell from Monthly to Annual | AN15: =AQ14 -> 3101.0088 | AO15: =AQ15-AN15 -> 661.93336 | AQ15: =Ctrl!N20 -> 3762.9422
G16: =Fin.Qtr!B18 -> Monthly Plan | K16: =Fin.Qtr!L18 -> 3471.2188 | L16: =Fin.Qtr!M18 -> 2131.7622 | M16: =Fin.Qtr!N18 -> 1309.1685 | N16: =Fin.Qtr!O18 -> 803.99309 | O16: =Fin.Qtr!P18 -> 493.75225 | P16: =Fin.Qtr!Q18 -> 303.2256 | Q16: =Fin.Qtr!R18 -> 186.21842 | R16: =Fin.Qtr!S18 -> 114.36139 | T16: =Fin.Qtr!U18 -> 1929.0356 | U16: =Fin.Qtr!V18 -> 274.38942 | AL16: Revised ARR | AP16: =AQ15 -> 3762.9422
B17: Founders' Equity | E17: =Fin.Mth!K68 -> 3000 | G17: =Fin.Qtr!B19 -> Annual Plan | K17: =Fin.Qtr!L19 -> 4915 | L17: =Fin.Qtr!M19 -> 6021.0863 | M17: =Fin.Qtr!N19 -> 7376.0897 | N17: =Fin.Qtr!O19 -> 9036.027 | O17: =Fin.Qtr!P19 -> 9188.5143 | P17: =Fin.Qtr!Q19 -> 10842.727 | Q17: =Fin.Qtr!R19 -> 12776.132 | R17: =Fin.Qtr!S19 -> 15030.612 | T17: =Fin.Qtr!U19 -> 6837.0508 | U17: =Fin.Qtr!V19 -> 11959.496
G18: =Fin.Qtr!B20 -> TOTAL | K18: =Fin.Qtr!L20 -> 8386.2188 | L18: =Fin.Qtr!M20 -> 8152.8486 | M18: =Fin.Qtr!N20 -> 8685.2581 | N18: =Fin.Qtr!O20 -> 9840.0201 | O18: =Fin.Qtr!P20 -> 9682.2666 | P18: =Fin.Qtr!Q20 -> 11145.953 | Q18: =Fin.Qtr!R20 -> 12962.35 | R18: =Fin.Qtr!S20 -> 15144.973 | T18: =Fin.Qtr!U20 -> 8766.0864 | U18: =Fin.Qtr!V20 -> 12233.886
B19: Runway (months) | E19: =Fin.Mth!K69 -> 16 | G19: =Fin.Qtr!B22 -> PRICING
B20: Buffer | E20: =Ctrl!H25 -> 6 | G20: =Fin.Qtr!B23 -> Monthly | K20: =Fin.Qtr!L23 -> 30 | L20: =Fin.Qtr!M23 -> 30 | M20: =Fin.Qtr!N23 -> 30 | N20: =Fin.Qtr!O23 -> 30 | O20: =Fin.Qtr!P23 -> 30 | P20: =Fin.Qtr!Q23 -> 30 | Q20: =Fin.Qtr!R23 -> 30 | R20: =Fin.Qtr!S23 -> 30 | T20: =Fin.Qtr!U23 -> 30 | U20: =Fin.Qtr!V23 -> 30
B21: Date of Fundraise | E21: =EOMONTH(E15,E19-E20) -> 45626 | G21: =Fin.Qtr!B24 -> Annual | K21: =Fin.Qtr!L24 -> 330 | L21: =Fin.Qtr!M24 -> 330 | M21: =Fin.Qtr!N24 -> 330 | N21: =Fin.Qtr!O24 -> 330 | O21: =Fin.Qtr!P24 -> 330 | P21: =Fin.Qtr!Q24 -> 330 | Q21: =Fin.Qtr!R24 -> 330 | R21: =Fin.Qtr!S24 -> 330 | T21: =Fin.Qtr!U24 -> 330 | U21: =Fin.Qtr!V24 -> 330
B22: Months from Today | E22: =YEARFRAC(E15,E21)*12 -> 10.966667 | G22: BLENDED | K22: =Fin.Qtr!L25 -> 21.697049 | L22: =Fin.Qtr!M25 -> 28.473223 | M22: =Fin.Qtr!N25 -> 27.714799 | N22: =Fin.Qtr!O25 -> 27.217225 | O22: =Fin.Qtr!P25 -> 22.245689 | P22: =Fin.Qtr!Q25 -> 17.802969 | Q22: =Fin.Qtr!R25 -> 17.198682 | R22: =Fin.Qtr!S25 -> 16.673421 | T22: =Fin.Qtr!U25 -> 26.275574 | U22: =Fin.Qtr!V25 -> 18.48019
G23: REVENUE METRICS
B24: Fundraising Calculations | G24: =Fin.Qtr!B28 -> Bookings | K24: =Fin.Qtr!L28 -> 1685.077 | L24: =Fin.Qtr!M28 -> 710.00898 | M24: =Fin.Qtr!N28 -> 584.70451 | N24: =Fin.Qtr!O28 -> 623.31876 | O24: =Fin.Qtr!P28 -> 670.03803 | P24: =Fin.Qtr!Q28 -> 693.26005 | Q24: =Fin.Qtr!R28 -> 794.96787 | R24: =Fin.Qtr!S28 -> 924.24868 | T24: =Fin.Qtr!U28 -> 900.77732 | U24: =Fin.Qtr!V28 -> 770.62866
B25: Cash Requirement by Dec-25 | E25: =-(Fin.Mth!K68+Fin.Mth!K66) -> 1759.9201 | G25: =Fin.Qtr!B29 -> Revenue | K25: =Fin.Qtr!L29 -> 468.61453 | L25: =Fin.Qtr!M29 -> 697.54207 | M25: =Fin.Qtr!N29 -> 703.13388 | N25: =Fin.Qtr!O29 -> 768.39983 | O25: =Fin.Qtr!P29 -> 637.06934 | P25: =Fin.Qtr!Q29 -> 567.61636 | Q25: =Fin.Qtr!R29 -> 635.97525 | R25: =Fin.Qtr!S29 -> 719.51004 | T25: =Fin.Qtr!U29 -> 659.42258 | U25: =Fin.Qtr!V29 -> 640.04275
B26: Add: Minimum Cash Balance | E26: =Ctrl!H24 -> 1500 | G26: =Fin.Qtr!B30 -> ARR | K26: =Fin.Qtr!L30 -> 2681.7469 | L26: =Fin.Qtr!M30 -> 2757.1137 | M26: =Fin.Qtr!N30 -> 2867.3752 | N26: =Fin.Qtr!O30 -> 3199.3266 | O26: =Fin.Qtr!P30 -> 2230.6737 | P26: =Fin.Qtr!Q30 -> 2351.8352 | Q26: =Fin.Qtr!R30 -> 2646.7928 | R26: =Fin.Qtr!S30 -> 2999.7355 | T26: =Fin.Qtr!U30 -> 2876.3906 | U26: =Fin.Qtr!V30 -> 2557.2593
B27: Add: Allowance for Growth | E27: =Ctrl!H26*(E17/E19) -> 0 | G27: SaaS METRICS
B28: Required Fundraise | E28: =SUM(E25:E27) -> 3259.9201 | G28: =Fin.Qtr!B33 -> CAC Payback (Monthly) | L28: =Fin.Qtr!M33 -> 7.9432271 | M28: =Fin.Qtr!N33 -> 7.8733974 | N28: =Fin.Qtr!O33 -> 7.8658393 | O28: =Fin.Qtr!P33 -> 7.6802094 | P28: =Fin.Qtr!Q33 -> 7.7217484 | Q28: =Fin.Qtr!R33 -> 7.7293888 | R28: =Fin.Qtr!S33 -> 7.7386804 | T28: =Fin.Qtr!U33 -> 7.8941546 | U28: =Fin.Qtr!V33 -> 7.7175067 | X28: Revenue by Monthly vs. Annual Plan | AE28: Cash Balance over Time | AL28: TORNADO CHART | AO28: Base Case ARR | AP28: =AQ13 -> 2999.7355
G29: =Fin.Qtr!B34 -> CAC Payback (Annual) | L29: =Fin.Qtr!M34 -> 0.72211156 | M29: =Fin.Qtr!N34 -> 0.7157634 | N29: =Fin.Qtr!O34 -> 0.7150763 | O29: =Fin.Qtr!P34 -> 0.69820085 | P29: =Fin.Qtr!Q34 -> 0.70197712 | Q29: =Fin.Qtr!R34 -> 0.70267171 | R29: =Fin.Qtr!S34 -> 0.7035164 | T29: =Fin.Qtr!U34 -> 0.71765042 | U29: =Fin.Qtr!V34 -> 0.70159152 | AL29: Scenario | AN29: Low | AO29: High | AP29: Low | AQ29: High
G30: =Fin.Qtr!B35 -> GDR (Monthly) | L30: =Fin.Qtr!M35 -> 0.75 | M30: =Fin.Qtr!N35 -> 0.75 | N30: =Fin.Qtr!O35 -> 0.75 | O30: =Fin.Qtr!P35 -> 0.75 | P30: =Fin.Qtr!Q35 -> 0.75 | Q30: =Fin.Qtr!R35 -> 0.75 | R30: =Fin.Qtr!S35 -> 0.75 | T30: =Fin.Qtr!U35 -> 0.75 | U30: =Fin.Qtr!V35 -> 0.75 | AL30: Launch Volumes | AN30: 9 | AO30: 8 | AP30: =SUMIF(Ctrl!$I$11:$W$11,AN30,Ctrl!$I$20:$W$20)-$AP$28 -> -299.97355 | AQ30: =SUMIF(Ctrl!$I$11:$W$11,AO30,Ctrl!$I$20:$W$20)-$AP$28 -> 299.97355
G31: =Fin.Qtr!B36 -> GDR (Annual) | L31: =Fin.Qtr!M36 -> 1 | M31: =Fin.Qtr!N36 -> 1 | N31: =Fin.Qtr!O36 -> 1 | O31: =Fin.Qtr!P36 -> 0.93586809 | P31: =Fin.Qtr!Q36 -> 0.98673092 | Q31: =Fin.Qtr!R36 -> 0.98621814 | R31: =Fin.Qtr!S36 -> 0.98566412 | T31: =Fin.Qtr!U36 -> 1 | U31: =Fin.Qtr!V36 -> 0.97362032 | AL31: Churn | AN31: 11 | AO31: 10 | AP31: =SUMIF(Ctrl!$I$11:$W$11,AN31,Ctrl!$I$20:$W$20)-$AP$28 -> -229.49098 | AQ31: =SUMIF(Ctrl!$I$11:$W$11,AO31,Ctrl!$I$20:$W$20)-$AP$28 -> 647.66967
AL32: MoM Growth | AN32: 13 | AO32: 12 | AP32: =SUMIF(Ctrl!$I$11:$W$11,AN32,Ctrl!$I$20:$W$20)-$AP$28 -> -576.28045 | AQ32: =SUMIF(Ctrl!$I$11:$W$11,AO32,Ctrl!$I$20:$W$20)-$AP$28 -> 674.21317
G33: Headcount | L33: =Fin.Qtr!M38 -> 10.333333 | M33: =Fin.Qtr!N38 -> 11.333333 | N33: =Fin.Qtr!O38 -> 13 | O33: =Fin.Qtr!P38 -> 13 | P33: =Fin.Qtr!Q38 -> 15 | Q33: =Fin.Qtr!R38 -> 16.666667 | R33: =Fin.Qtr!S38 -> 18.666667 | T33: =Fin.Qtr!U38 -> 10.5 | U33: =Fin.Qtr!V38 -> 15.833333 | AL33: Pricing | AN33: 15 | AO33: 14 | AP33: =SUMIF(Ctrl!$I$11:$W$11,AN33,Ctrl!$I$20:$W$20)-$AP$28 -> -299.97355 | AQ33: =SUMIF(Ctrl!$I$11:$W$11,AO33,Ctrl!$I$20:$W$20)-$AP$28 -> 299.97355
G34: Bookings / FTE | L34: =L24/L33 -> 68.710547 | M34: =M24/M33 -> 51.591574 | N34: =N24/N33 -> 47.947597 | O34: =O24/O33 -> 51.541387 | P34: =P24/P33 -> 46.217337 | Q34: =Q24/Q33 -> 47.698072 | R34: =R24/R33 -> 49.513322 | T34: =AVERAGE(L34:O34) -> 54.947776 | U34: =AVERAGE(O34:R34) -> 48.74253
G35: Bookings / Headcount Cost | L35: =-L24/L46 -> 1.7149975 | M35: =-M24/M46 -> 1.2554042 | N35: =-N24/N46 -> 1.1088713 | O35: =-O24/O46 -> 1.1180997 | P35: =-P24/P46 -> 1.0012204 | Q35: =-Q24/Q46 -> 1.0241132 | R35: =-R24/R46 -> 1.063088 | T35: =AVERAGE(L35:O35) -> 1.2993432 | U35: =AVERAGE(O35:R35) -> 1.0516303
G36: Bookings / S&M | L36: =-L24/L48 -> 1.7758594 | M36: =-M24/M48 -> 1.5359482 | N36: =-N24/N48 -> 1.560856 | O36: =-O24/O48 -> 1.6110057 | P36: =-P24/P48 -> 1.5985809 | Q36: =-Q24/Q48 -> 1.5991079 | R36: =-R24/R48 -> 1.6027271 | T36: =AVERAGE(L36:O36) -> 1.6209173 | U36: =AVERAGE(O36:R36) -> 1.6028554
G38: SUMMARY FINANCIALS
G39: Monthly Plan | K39: =Fin.Qtr!L42 -> 225.32203 | L39: =Fin.Qtr!M42 -> 247.79946 | M39: =Fin.Qtr!N42 -> 152.17984 | N39: =Fin.Qtr!O42 -> 93.457446 | O39: =Fin.Qtr!P42 -> 57.394554 | P39: =Fin.Qtr!Q42 -> 35.24743 | Q39: =Fin.Qtr!R42 -> 21.646328 | R39: =Fin.Qtr!S42 -> 13.293551 | T39: =Fin.Qtr!U42 -> 718.75878 | U39: =Fin.Qtr!V42 -> 127.58186
G40: Annual Plan | K40: =Fin.Qtr!L43 -> 243.2925 | L40: =Fin.Qtr!M43 -> 449.74261 | M40: =Fin.Qtr!N43 -> 550.95403 | N40: =Fin.Qtr!O43 -> 674.94238 | O40: =Fin.Qtr!P43 -> 579.67479 | P40: =Fin.Qtr!Q43 -> 532.36893 | Q40: =Fin.Qtr!R43 -> 614.32893 | R40: =Fin.Qtr!S43 -> 706.21648 | T40: =Fin.Qtr!U43 -> 1918.9315 | U40: =Fin.Qtr!V43 -> 2432.5891
G41: Total Revenue | K41: =Fin.Qtr!L44 -> 468.61453 | L41: =Fin.Qtr!M44 -> 697.54207 | M41: =Fin.Qtr!N44 -> 703.13388 | N41: =Fin.Qtr!O44 -> 768.39983 | O41: =Fin.Qtr!P44 -> 637.06934 | P41: =Fin.Qtr!Q44 -> 567.61636 | Q41: =Fin.Qtr!R44 -> 635.97525 | R41: =Fin.Qtr!S44 -> 719.51004 | T41: =Fin.Qtr!U44 -> 2637.6903 | U41: =Fin.Qtr!V44 -> 2560.171
G42: % growth | L42: =L41/K41-1 -> 0.48851993 | M42: =M41/L41-1 -> 0.0080164478 | N42: =N41/M41-1 -> 0.092821515 | O42: =O41/N41-1 -> -0.17091426 | P42: =P41/O41-1 -> -0.1090195 | Q42: =Q41/P41-1 -> 0.1204315 | R42: =R41/Q41-1 -> 0.13134911 | U42: =U41/T41-1 -> -0.029389088
G43: Gross Profit | K43: =Fin.Qtr!L46 -> 344.97771 | L43: =Fin.Qtr!M46 -> 585.43666 | M43: =Fin.Qtr!N46 -> 595.36963 | N43: =Fin.Qtr!O46 -> 651.2591 | O43: =Fin.Qtr!P46 -> 553.26127 | P43: =Fin.Qtr!Q46 -> 490.05692 | Q43: =Fin.Qtr!R46 -> 548.52869 | R43: =Fin.Qtr!S46 -> 619.83157 | T43: =Fin.Qtr!U46 -> 2177.0431 | U43: =Fin.Qtr!V46 -> 2211.6785
G44: % margin | K44: =K43/K41 -> 0.73616519 | L44: =L43/L41 -> 0.83928509 | M44: =M43/M41 -> 0.84673723 | N44: =N43/N41 -> 0.84755237 | O44: =O43/O41 -> 0.86844748 | P44: =P43/P41 -> 0.8633594 | Q44: =Q43/Q41 -> 0.86250006 | R44: =R43/R41 -> 0.86146341 | T44: =T43/T41 -> 0.82535963 | U44: =U43/U41 -> 0.86387919 | X44: Dollar Retention & Payback by Plan | AE44: Churn Reduction | AG44: Base | AH44: Inc | AI44: End | AJ44: ARR
AE45: Base Case ARR | AI45: =AJ45 -> 2999.7355 | AJ45: =Ctrl!I20 -> 2999.7355
G46: =Fin.Qtr!B48 -> Headcount Costs | K46: =Fin.Qtr!L48 -> -284.625 | L46: =Fin.Qtr!M48 -> -414 | M46: =Fin.Qtr!N48 -> -465.75 | N46: =Fin.Qtr!O48 -> -562.12 | O46: =Fin.Qtr!P48 -> -599.265 | P46: =Fin.Qtr!Q48 -> -692.415 | Q46: =Fin.Qtr!R48 -> -776.25 | R46: =Fin.Qtr!S48 -> -869.4 | T46: =Fin.Qtr!U48 -> -1726.495 | U46: =Fin.Qtr!V48 -> -2937.33 | AE46: Add: ARR from Monthly Churn Reduction | AG46: =AI45 -> 2999.7355 | AH46: =AJ46-AI45 -> 460.00491 | AJ46: =Ctrl!K20 -> 3459.7404
G47: =Fin.Qtr!B49 -> G&A | K47: =Fin.Qtr!L49 -> -61.4 | L47: =Fin.Qtr!M49 -> -65.698 | M47: =Fin.Qtr!N49 -> -70.29686 | N47: =Fin.Qtr!O49 -> -75.21764 | O47: =Fin.Qtr!P49 -> -80.482875 | P47: =Fin.Qtr!Q49 -> -86.116676 | Q47: =Fin.Qtr!R49 -> -92.144844 | R47: =Fin.Qtr!S49 -> -98.594983 | T47: =Fin.Qtr!U49 -> -272.6125 | U47: =Fin.Qtr!V49 -> -357.33938 | AE47: Add: ARR from Annual Churn Reduction | AG47: =AJ46 -> 3459.7404 | AH47: =AJ47-AG47 -> 187.66476 | AJ47: =Ctrl!L20 -> 3647.4052
G48: =Fin.Qtr!B50 -> S&M | K48: =Fin.Qtr!L50 -> -1966 | L48: =Fin.Qtr!M50 -> -399.81147 | M48: =Fin.Qtr!N50 -> -380.67983 | N48: =Fin.Qtr!O50 -> -399.34419 | O48: =Fin.Qtr!P50 -> -415.9129 | P48: =Fin.Qtr!Q50 -> -433.67216 | Q48: =Fin.Qtr!R50 -> -497.1321 | R48: =Fin.Qtr!S50 -> -576.67254 | T48: =Fin.Qtr!U50 -> -3145.8355 | U48: =Fin.Qtr!V50 -> -1923.3897 | AE48: Revised ARR | AI48: =AJ47 -> 3647.4052
...

Sheet Calc>
B9: Project Eagle
B10: Operating Model
B11: Operating Calculations

Sheet Calc.Mth
B3: Project Eagle
B4: Calculations | Monthly | G4: Runway | H4: Fundraise | I4: Fund. Date | J4: End. ARR | K4: Deferred Rev.
B5: =Ctrl!$B$5 -> CASE 1: BASE CASE | G5: =Sum!$E$19 -> 16 | H5: =Sum!$E$28 -> 3259.9201 | I5: =Sum!$E$21 -> 45626 | J5: ='Calc.Mth'!$AI$57 -> 2999.7355 | K5: =Fin.Mth!$AI$81 -> 1487.7626
B7: Period End | L7: 45322 | M7: =EOMONTH(M8,0) -> 45351 | N7: =EOMONTH(N8,0) -> 45382 | O7: =EOMONTH(O8,0) -> 45412 | P7: =EOMONTH(P8,0) -> 45443 | Q7: =EOMONTH(Q8,0) -> 45473 | R7: =EOMONTH(R8,0) -> 45504 | S7: =EOMONTH(S8,0) -> 45535 | T7: =EOMONTH(T8,0) -> 45565 | ... AI7: =EOMONTH(AI8,0) -> 46022
B8: Period Start | L8: 45292 | M8: =L7+1 -> 45323 | N8: =M7+1 -> 45352 | O8: =N7+1 -> 45383 | P8: =O7+1 -> 45413 | Q8: =P7+1 -> 45444 | R8: =Q7+1 -> 45474 | S8: =R7+1 -> 45505 | T8: =S7+1 -> 45536 | ... AI8: =AH7+1 -> 45992
B9: Calendar Year | L9: =YEAR(L7) -> 2024 | M9: =YEAR(M7) -> 2024 | N9: =YEAR(N7) -> 2024 | O9: =YEAR(O7) -> 2024 | P9: =YEAR(P7) -> 2024 | Q9: =YEAR(Q7) -> 2024 | R9: =YEAR(R7) -> 2024 | S9: =YEAR(S7) -> 2024 | ... AI9: =YEAR(AI7) -> 2025
B10: Period Number | L10: 1 | M10: =L10+1 -> 2 | N10: =M10+1 -> 3 | O10: =N10+1 -> 4 | P10: =O10+1 -> 5 | Q10: =P10+1 -> 6 | R10: =Q10+1 -> 7 | S10: =R10+1 -> 8 | T10: =S10+1 -> 9 | ... AI10: =AH10+1 -> 24
B11: Days in Period | F11: Units | H11: Input I | I11: Input II | J11: Input III | K11: Total / Out | L11: =L7-L8+1 -> 31 | M11: =M7-M8+1 -> 29 | N11: =N7-N8+1 -> 31 | O11: =O7-O8+1 -> 30 | P11: =P7-P8+1 -> 31 | Q11: =Q7-Q8+1 -> 30 | R11: =R7-R8+1 -> 31 | S11: =S7-S8+1 -> 31 | ... AI11: =AI7-AI8+1 -> 31
A15: X | B15: TIMING & FLAGS
B17: January Point-to-Point | F17: # | H17: 12 | L17: =(MONTH(L7)=$H17)*1 -> 0 | M17: =(MONTH(M7)=$H17)*1 -> 0 | N17: =(MONTH(N7)=$H17)*1 -> 0 | O17: =(MONTH(O7)=$H17)*1 -> 0 | P17: =(MONTH(P7)=$H17)*1 -> 0 | Q17: =(MONTH(Q7)=$H17)*1 -> 0 | R17: =(MONTH(R7)=$H17)*1 -> 0 | S17: =(MONTH(S7)=$H17)*1 -> 0 | ... AI17: =(MONTH(AI7)=$H17)*1 -> 1
B18: Quarterly Point-to-Point | F18: # | L18: =(MOD(L10,3)=0)*1 -> 0 | M18: =(MOD(M10,3)=0)*1 -> 0 | N18: =(MOD(N10,3)=0)*1 -> 1 | O18: =(MOD(O10,3)=0)*1 -> 0 | P18: =(MOD(P10,3)=0)*1 -> 0 | Q18: =(MOD(Q10,3)=0)*1 -> 1 | R18: =(MOD(R10,3)=0)*1 -> 0 | S18: =(MOD(S10,3)=0)*1 -> 0 | ... AI18: =(MOD(AI10,3)=0)*1 -> 1
B19: Annual Plan - Rolling LTM Counter | F19: # | L19: =MIN(L10,$H17) -> 1 | M19: =MIN(M10,$H17) -> 2 | N19: =MIN(N10,$H17) -> 3 | O19: =MIN(O10,$H17) -> 4 | P19: =MIN(P10,$H17) -> 5 | Q19: =MIN(Q10,$H17) -> 6 | R19: =MIN(R10,$H17) -> 7 | S19: =MIN(S10,$H17) -> 8 | ... AI19: =MIN(AI10,$H17) -> 12
B21: MILESTONE FLAGS
B22: ARR Milestone? | F22: # | H22: =Ctrl!H56 -> 750 | L22: =ROUNDDOWN(L57/$H22,0) -> 1 | M22: =ROUNDDOWN(M57/$H22,0) -> 2 | N22: =ROUNDDOWN(N57/$H22,0) -> 3 | O22: =ROUNDDOWN(O57/$H22,0) -> 3 | P22: =ROUNDDOWN(P57/$H22,0) -> 3 | Q22: =ROUNDDOWN(Q57/$H22,0) -> 3 | R22: =ROUNDDOWN(R57/$H22,0) -> 3 | S22: =ROUNDDOWN(S57/$H22,0) -> 3 | ... AI22: =ROUNDDOWN(AI57/$H22,0) -> 3
B23: Customer Milestone | F23: # | H23: =Ctrl!H57 -> 2500 | L23: =ROUNDDOWN(L30/$H23,0) -> 1 | M23: =ROUNDDOWN(M30/$H23,0) -> 2 | N23: =ROUNDDOWN(N30/$H23,0) -> 3 | O23: =ROUNDDOWN(O30/$H23,0) -> 3 | P23: =ROUNDDOWN(P30/$H23,0) -> 3 | Q23: =ROUNDDOWN(Q30/$H23,0) -> 3 | R23: =ROUNDDOWN(R30/$H23,0) -> 3 | S23: =ROUNDDOWN(S30/$H23,0) -> 3 | ... AI23: =ROUNDDOWN(AI30/$H23,0) -> 6
B24: Headcount Milestone | F24: # | H24: =Ctrl!H58 -> 20 | K24: 1 | L24: =K24+(MOD(L98,20)=0) -> 1 | M24: =L24+(MOD(M98,20)=0) -> 1 | N24: =M24+(MOD(N98,20)=0) -> 1 | O24: =N24+(MOD(O98,20)=0) -> 1 | P24: =O24+(MOD(P98,20)=0) -> 1 | Q24: =P24+(MOD(Q98,20)=0) -> 1 | R24: =Q24+(MOD(R98,20)=0) -> 1 | S24: =R24+(MOD(S98,20)=0) -> 1 | ... AI24: =AH24+(MOD(AI98,20)=0) -> 2
B26: Launch Phasing | F26: # | L26: =Ctrl!H34 -> 0.5 | M26: =Ctrl!H35 -> 0.3 | N26: =Ctrl!H36 -> 0.2
A28: X | B28: SUBSCRIBERS
B30: Total Customers | F30: # | L30: =SUM(L38,L48) -> 4915 | M30: =SUM(M38,M48) -> 7249.625 | N30: =SUM(N38,N48) -> 8386.2188 | O30: =SUM(O38,O48) -> 8209.5859 | P30: =SUM(P38,P48) -> 8135.139 | Q30: =SUM(Q38,Q48) -> 8152.8486 | R30: =SUM(R38,R48) -> 8254.5603 | S30: =SUM(S38,S48) -> 8433.74 | ... AI30: =SUM(AI38,AI48) -> 15144.973
B32: MONTHLY PLAN
B33: Opening | F33: # | L33: =K38 -> 0 | M33: =L38 -> 2457.5 | N33: =M38 -> 3317.625 | O33: =N38 -> 3471.2188 | P33: =O38 -> 2950.5359 | Q33: =P38 -> 2507.9555 | R33: =Q38 -> 2131.7622 | S33: =R38 -> 1811.9979 | ... AI33: =AH38 -> 134.54281
B34: Additions | F34: # | L34: =Ctrl!$H$31/2*L26 -> 2457.5 | M34: =Ctrl!$H$31/2*M26 -> 1474.5 | N34: =Ctrl!$H$31/2*N26 -> 983 | O34: =O35*O33 -> 347.12188 | P34: =P35*P33 -> 295.05359 | Q34: =Q35*Q33 -> 250.79555 | R34: =R35*R33 -> 213.17622 | S34: =S35*S33 -> 181.19979 | T34: =T35*T33 -> 154.01982 | U34: =U35*U33 -> 130.91685 | V34: =V35*V33 -> 111.27932 | ... AI34: =AI35*AI33 -> 13.454281
B35: % adds | F35: % | L35: =Ctrl!H39 -> 0.1 | M35: =L35 -> 0.1 | N35: =M35 -> 0.1 | O35: =N35 -> 0.1 | P35: =O35 -> 0.1 | Q35: =P35 -> 0.1 | R35: =Q35 -> 0.1 | S35: =R35 -> 0.1 | T35: =S35 -> 0.1 | ... AI35: =AH35 -> 0.1
B36: Churn | F36: # | L36: =-L33*L37 -> 0 | M36: =-M33*M37 -> -614.375 | N36: =-N33*N37 -> -829.40625 | O36: =-O33*O37 -> -867.80469 | P36: =-P33*P37 -> -737.63398 | Q36: =-Q33*Q37 -> -626.98889 | R36: =-R33*R37 -> -532.94055 | S36: =-S33*S37 -> -452.99947 | ... AI36: =-AI33*AI37 -> -33.635703
B37: % churn | F37: % | L37: =Ctrl!H43 -> 0.25 | M37: =L37 -> 0.25 | N37: =M37 -> 0.25 | O37: =N37 -> 0.25 | P37: =O37 -> 0.25 | Q37: =P37 -> 0.25 | R37: =Q37 -> 0.25 | S37: =R37 -> 0.25 | T37: =S37 -> 0.25 | ... AI37: =AH37 -> 0.25
B38: CLOSING | F38: # | K38: 0 | L38: =SUM(L33:L34,L36) -> 2457.5 | M38: =SUM(M33:M34,M36) -> 3317.625 | N38: =SUM(N33:N34,N36) -> 3471.2188 | O38: =SUM(O33:O34,O36) -> 2950.5359 | P38: =SUM(P33:P34,P36) -> 2507.9555 | Q38: =SUM(Q33:Q34,Q36) -> 2131.7622 | R38: =SUM(R33:R34,R36) -> 1811.9979 | S38: =SUM(S33:S34,S36) -> 1540.1982 | ... AI38: =SUM(AI33:AI34,AI36) -> 114.36139
B39: % net adds - MoM | F39: % | M39: =M38/L38-1 -> 0.35 | N39: =N38/M38-1 -> 0.046296296 | O39: =O38/N38-1 -> -0.15 | P39: =P38/O38-1 -> -0.15 | Q39: =Q38/P38-1 -> -0.15 | R39: =R38/Q38-1 -> -0.15 | S39: =S38/R38-1 -> -0.15 | T39: =T38/S38-1 -> -0.15 | ... AI39: =AI38/AH38-1 -> -0.15
B40: % net adds - YoY | F40: % | X40: =X38/L38-1 -> -0.7219149 | Y40: =Y38/M38-1 -> -0.82490938 | Z40: =Z38/N38-1 -> -0.85775824 | AA40: =AA38/O38-1 -> -0.85775824 | AB40: =AB38/P38-1 -> -0.85775824 | AC40: =AC38/Q38-1 -> -0.85775824 | AD40: =AD38/R38-1 -> -0.85775824 | AE40: =AE38/S38-1 -> -0.85775824 | ... AI40: =AI38/W38-1 -> -0.85775824
B42: ANNUAL PLAN
B43: Opening | F43: # | K43: =K48-K44 -> 0 | L43: =K48 -> 0 | M43: =L48 -> 2457.5 | N43: =M48 -> 3932 | O43: =N48 -> 4915 | P43: =O48 -> 5259.05 | Q43: =P48 -> 5627.1835 | R43: =Q48 -> 6021.0863 | S43: =R48 -> 6442.5624 | ... AI43: =AH48 -> 14240.665
B44: Additions | F44: # | K44: =K48 -> 0 | L44: =Ctrl!$H$31/2*L26 -> 2457.5 | M44: =Ctrl!$H$31/2*M26 -> 1474.5 | N44: =Ctrl!$H$31/2*N26 -> 983 | O44: =O45*O43 -> 344.05 | P44: =P45*P43 -> 368.1335 | Q44: =Q45*Q43 -> 393.90285 | R44: =R45*R43 -> 421.47604 | S44: =S45*S43 -> 450.97937 | T44: =T45*T43 -> 482.54792 | U44: =U45*U43 -> 516.32628 | V44: =V45*V43 -> 552.46912 | ... AI44: =AI45*AI43 -> 996.84653
B45: % adds | F45: % | L45: =Ctrl!H40 -> 0.07 | M45: =L45 -> 0.07 | N45: =M45 -> 0.07 | O45: =N45 -> 0.07 | P45: =O45 -> 0.07 | Q45: =P45 -> 0.07 | R45: =Q45 -> 0.07 | S45: =R45 -> 0.07 | T45: =S45 -> 0.07 | ... AI45: =AH45 -> 0.07
B46: Churn | F46: # | L46: =IF(SUM($L17:L17)>0,-OFFSET(L44,,-$H$17)*L47,0) -> 0 | M46: =IF(SUM($L17:M17)>0,-OFFSET(M44,,-$H$17)*M47,0) -> 0 | N46: =IF(SUM($L17:N17)>0,-OFFSET(N44,,-$H$17)*N47,0) -> 0 | O46: =IF(SUM($L17:O17)>0,-OFFSET(O44,,-$H$17)*O47,0) -> 0 | P46: =IF(SUM($L17:P17)>0,-OFFSET(P44,,-$H$17)*P47,0) -> 0 | Q46: =IF(SUM($L17:Q17)>0,-OFFSET(Q44,,-$H$17)*Q47,0) -> 0 | R46: =IF(SUM($L17:R17)>0,-OFFSET(R44,,-$H$17)*R47,0) -> 0 | S46: =IF(SUM($L17:S17)>0,-OFFSET(S44,,-$H$17)*S47,0) -> 0 | ... AI46: =IF(SUM($L17:AI17)>0,-OFFSET(AI44,,-$H$17)*AI47,0) -> -206.89968
B47: % churn | F47: % | H47: =Ctrl!H44 -> 0.35 | L47: =$H47*(SUM($L17:L17)>0) -> 0 | M47: =$H47*(SUM($L17:M17)>0) -> 0 | N47: =$H47*(SUM($L17:N17)>0) -> 0 | O47: =$H47*(SUM($L17:O17)>0) -> 0 | P47: =$H47*(SUM($L17:P17)>0) -> 0 | Q47: =$H47*(SUM($L17:Q17)>0) -> 0 | R47: =$H47*(SUM($L17:R17)>0) -> 0 | S47: =$H47*(SUM($L17:S17)>0) -> 0 | ... AI47: =$H47*(SUM($L17:AI17)>0) -> 0.35
B48: CLOSING | F48: # | K48: 0 | L48: =SUM(L43:L44,L46) -> 2457.5 | M48: =SUM(M43:M44,M46) -> 3932 | N48: =SUM(N43:N44,N46) -> 4915 | O48: =SUM(O43:O44,O46) -> 5259.05 | P48: =SUM(P43:P44,P46) -> 5627.1835 | Q48: =SUM(Q43:Q44,Q46) -> 6021.0863 | R48: =SUM(R43:R44,R46) -> 6442.5624 | S48: =SUM(S43:S44,S46) -> 6893.5418 | ... AI48: =SUM(AI43:AI44,AI46) -> 15030.612
B49: % net adds - MoM | F49: % | M49: =M48/L48-1 -> 0.6 | N49: =N48/M48-1 -> 0.25 | O49: =O48/N48-1 -> 0.07 | P49: =P48/O48-1 -> 0.07 | Q49: =Q48/P48-1 -> 0.07 | R49: =R48/Q48-1 -> 0.07 | S49: =S48/R48-1 -> 0.07 | T49: =T48/S48-1 -> 0.07 | ... AI49: =AI48/AH48-1 -> 0.055471206
B50: % net adds - YoY | F50: % | X50: =X48/L48-1 -> 2.5843027 | Y50: =Y48/M48-1 -> 1.2657524 | Z50: =Z48/N48-1 -> 0.86948409 | AA50: =AA48/O48-1 -> 0.84658689 | AB50: =AB48/P48-1 -> 0.8236897 | AC50: =AC48/Q48-1 -> 0.8007925 | AD50: =AD48/R48-1 -> 0.7778953 | AE50: =AE48/S48-1 -> 0.75499811 | ... AI50: =AI48/W48-1 -> 0.66340932
A52: X | B52: REVENUE
B54: SUMMARY
B55: Revenue | F55: $k | L55: =SUM(L62,L70) -> 70.653125 | M55: =SUM(M62,M70) -> 174.4825 | N55: =SUM(N62,N70) -> 223.47891 | O55: =SUM(O62,O70) -> 236.21951 | P55: =SUM(P62,P70) -> 231.56308 | Q55: =SUM(Q62,Q70) -> 229.75948 | R55: =SUM(R62,R70) -> 230.53157 | S55: =SUM(S62,S70) -> 233.65437 | ... AI55: =SUM(AI62,AI70) -> 249.97796
...

Sheet Fin>
B9: Project Eagle
B10: Operating Model
B11: Summary Financials

Sheet Fin.Mth
B3: ='Calc.Mth'!B3 -> Project Eagle
B4: Summary Financials | Monthly | G4: Runway | H4: Fundraise | I4: Fund. Date | J4: End. ARR | K4: Deferred Rev.
B5: =Ctrl!$B$5 -> CASE 1: BASE CASE | G5: =Sum!$E$19 -> 16 | H5: =Sum!$E$28 -> 3259.9201 | I5: =Sum!$E$21 -> 45626 | J5: ='Calc.Mth'!$AI$57 -> 2999.7355 | K5: =Fin.Mth!$AI$81 -> 1487.7626
B7: ='Calc.Mth'!B7 -> Period End | L7: ='Calc.Mth'!L7 -> 45322 | M7: ='Calc.Mth'!M7 -> 45351 | N7: ='Calc.Mth'!N7 -> 45382 | O7: ='Calc.Mth'!O7 -> 45412 | P7: ='Calc.Mth'!P7 -> 45443 | Q7: ='Calc.Mth'!Q7 -> 45473 | R7: ='Calc.Mth'!R7 -> 45504 | S7: ='Calc.Mth'!S7 -> 45535 | ... AI7: ='Calc.Mth'!AI7 -> 46022
B8: ='Calc.Mth'!B8 -> Period Start | L8: ='Calc.Mth'!L8 -> 45292 | M8: ='Calc.Mth'!M8 -> 45323 | N8: ='Calc.Mth'!N8 -> 45352 | O8: ='Calc.Mth'!O8 -> 45383 | P8: ='Calc.Mth'!P8 -> 45413 | Q8: ='Calc.Mth'!Q8 -> 45444 | R8: ='Calc.Mth'!R8 -> 45474 | S8: ='Calc.Mth'!S8 -> 45505 | ... AI8: ='Calc.Mth'!AI8 -> 45992
B9: ='Calc.Mth'!B9 -> Calendar Year | L9: ='Calc.Mth'!L9 -> 2024 | M9: ='Calc.Mth'!M9 -> 2024 | N9: ='Calc.Mth'!N9 -> 2024 | O9: ='Calc.Mth'!O9 -> 2024 | P9: ='Calc.Mth'!P9 -> 2024 | Q9: ='Calc.Mth'!Q9 -> 2024 | R9: ='Calc.Mth'!R9 -> 2024 | S9: ='Calc.Mth'!S9 -> 2024 | ... AI9: ='Calc.Mth'!AI9 -> 2025
B10: ='Calc.Mth'!B10 -> Period Number | L10: ='Calc.Mth'!L10 -> 1 | M10: ='Calc.Mth'!M10 -> 2 | N10: ='Calc.Mth'!N10 -> 3 | O10: ='Calc.Mth'!O10 -> 4 | P10: ='Calc.Mth'!P10 -> 5 | Q10: ='Calc.Mth'!Q10 -> 6 | R10: ='Calc.Mth'!R10 -> 7 | S10: ='Calc.Mth'!S10 -> 8 | ... AI10: ='Calc.Mth'!AI10 -> 24
B11: ='Calc.Mth'!B11 -> Days in Period | F11: ='Calc.Mth'!F11 -> Units | H11: ='Calc.Mth'!H11 -> Input I | I11: ='Calc.Mth'!I11 -> Input II | J11: ='Calc.Mth'!J11 -> Input III | K11: ='Calc.Mth'!K11 -> Total / Out | L11: ='Calc.Mth'!L11 -> 31 | M11: ='Calc.Mth'!M11 -> 29 | N11: ='Calc.Mth'!N11 -> 31 | O11: ='Calc.Mth'!O11 -> 30 | ... AI11: ='Calc.Mth'!AI11 -> 31
A15: X | B15: OPERATING METRICS
B17: # CUSTOMERS
B18: Monthly Plan | F18: # | L18: ='Calc.Mth'!L38 -> 2457.5 | M18: ='Calc.Mth'!M38 -> 3317.625 | N18: ='Calc.Mth'!N38 -> 3471.2188 | O18: ='Calc.Mth'!O38 -> 2950.5359 | P18: ='Calc.Mth'!P38 -> 2507.9555 | Q18: ='Calc.Mth'!Q38 -> 2131.7622 | R18: ='Calc.Mth'!R38 -> 1811.9979 | S18: ='Calc.Mth'!S38 -> 1540.1982 | ... AI18: ='Calc.Mth'!AI38 -> 114.36139
B19: Annual Plan | F19: # | L19: ='Calc.Mth'!L48 -> 2457.5 | M19: ='Calc.Mth'!M48 -> 3932 | N19: ='Calc.Mth'!N48 -> 4915 | O19: ='Calc.Mth'!O48 -> 5259.05 | P19: ='Calc.Mth'!P48 -> 5627.1835 | Q19: ='Calc.Mth'!Q48 -> 6021.0863 | R19: ='Calc.Mth'!R48 -> 6442.5624 | S19: ='Calc.Mth'!S48 -> 6893.5418 | ... AI19: ='Calc.Mth'!AI48 -> 15030.612
B20: TOTAL | F20: # | L20: =SUM(L18:L19) -> 4915 | M20: =SUM(M18:M19) -> 7249.625 | N20: =SUM(N18:N19) -> 8386.2188 | O20: =SUM(O18:O19) -> 8209.5859 | P20: =SUM(P18:P19) -> 8135.139 | Q20: =SUM(Q18:Q19) -> 8152.8486 | R20: =SUM(R18:R19) -> 8254.5603 | S20: =SUM(S18:S19) -> 8433.74 | ... AI20: =SUM(AI18:AI19) -> 15144.973
B22: PRICING
B23: Monthly | F23: $k | L23: ='Calc.Mth'!L61 -> 30 | M23: ='Calc.Mth'!M61 -> 30 | N23: ='Calc.Mth'!N61 -> 30 | O23: ='Calc.Mth'!O61 -> 30 | P23: ='Calc.Mth'!P61 -> 30 | Q23: ='Calc.Mth'!Q61 -> 30 | R23: ='Calc.Mth'!R61 -> 30 | S23: ='Calc.Mth'!S61 -> 30 | ... AI23: ='Calc.Mth'!AI61 -> 30
B24: Annual | F24: $k | L24: ='Calc.Mth'!L67 -> 330 | M24: ='Calc.Mth'!M67 -> 330 | N24: ='Calc.Mth'!N67 -> 330 | O24: ='Calc.Mth'!O67 -> 330 | P24: ='Calc.Mth'!P67 -> 330 | Q24: ='Calc.Mth'!Q67 -> 330 | R24: ='Calc.Mth'!R67 -> 330 | S24: ='Calc.Mth'!S67 -> 330 | ... AI24: ='Calc.Mth'!AI67 -> 330
B25: TOTAL | F25: $k | L25: =L29/L20*10^3 -> 14.375 | M25: =M29/M20*10^3 -> 24.067797 | N25: =N29/N20*10^3 -> 26.648352 | O25: =O29/O20*10^3 -> 28.77362 | P25: =P29/P20*10^3 -> 28.464551 | Q25: =Q29/Q20*10^3 -> 28.181497 | R25: =R29/R20*10^3 -> 27.927783 | S25: =S29/S20*10^3 -> 27.704716 | ... AI25: =AI29/AI20*10^3 -> 16.505672
B27: REVENUE METRICS
B28: Bookings | F28: $k | L28: ='Calc.Mth'!L56 -> 442.35 | M28: ='Calc.Mth'!M56 -> 735.40688 | N28: ='Calc.Mth'!N56 -> 507.32016 | O28: ='Calc.Mth'!O56 -> 315.28957 | P28: ='Calc.Mth'!P56 -> 199.38765 | Q28: ='Calc.Mth'!Q56 -> 195.33176 | R28: ='Calc.Mth'!R56 -> 193.69392 | S28: ='Calc.Mth'!S56 -> 194.23808 | ... AI28: ='Calc.Mth'!AI56 -> 324.01981
B29: Revenue | F29: $k | L29: ='Calc.Mth'!L55 -> 70.653125 | M29: ='Calc.Mth'!M55 -> 174.4825 | N29: ='Calc.Mth'!N55 -> 223.47891 | O29: ='Calc.Mth'!O55 -> 236.21951 | P29: ='Calc.Mth'!P55 -> 231.56308 | Q29: ='Calc.Mth'!Q55 -> 229.75948 | R29: ='Calc.Mth'!R55 -> 230.53157 | S29: ='Calc.Mth'!S55 -> 233.65437 | ... AI29: ='Calc.Mth'!AI55 -> 249.97796
B30: ARR | F30: $k | L30: ='Calc.Mth'!L57 -> 847.8375 | M30: ='Calc.Mth'!M57 -> 2093.79 | N30: ='Calc.Mth'!N57 -> 2681.7469 | O30: ='Calc.Mth'!O57 -> 2834.6341 | P30: ='Calc.Mth'!P57 -> 2778.757 | Q30: ='Calc.Mth'!Q57 -> 2757.1137 | R30: ='Calc.Mth'!R57 -> 2766.3789 | S30: ='Calc.Mth'!S57 -> 2803.8525 | ... AI30: ='Calc.Mth'!AI57 -> 2999.7355
B32: SaaS METRICS
B33: CAC Payback (Monthly Plan) | F33: months | M33: ='Calc.Mth'!M129/('Calc.Mth'!M61*M47) -> 9.3710816 | N33: ='Calc.Mth'!N129/('Calc.Mth'!N61*N47) -> 8.447417 | O33: ='Calc.Mth'!O129/('Calc.Mth'!O61*O47) -> 8.0650617 | P33: ='Calc.Mth'!P129/('Calc.Mth'!P61*P47) -> 7.8843403 | Q33: ='Calc.Mth'!Q129/('Calc.Mth'!Q61*Q47) -> 7.8802794 | R33: ='Calc.Mth'!R129/('Calc.Mth'!R61*R47) -> 7.8765731 | S33: ='Calc.Mth'!S129/('Calc.Mth'!S61*S47) -> 7.8732613 | T33: ='Calc.Mth'!T129/('Calc.Mth'!T61*T47) -> 7.8703577 | ... AI33: ='Calc.Mth'!AI129/('Calc.Mth'!AI61*AI47) -> 7.7419078
B34: CAC Payback (Annual Plan) | F34: months | M34: ='Calc.Mth'!M129/('Calc.Mth'!M67*M47) -> 0.85191651 | N34: ='Calc.Mth'!N129/('Calc.Mth'!N67*N47) -> 0.767947 | O34: ='Calc.Mth'!O129/('Calc.Mth'!O67*O47) -> 0.73318743 | P34: ='Calc.Mth'!P129/('Calc.Mth'!P67*P47) -> 0.71675821 | Q34: ='Calc.Mth'!Q129/('Calc.Mth'!Q67*Q47) -> 0.71638903 | R34: ='Calc.Mth'!R129/('Calc.Mth'!R67*R47) -> 0.7160521 | S34: ='Calc.Mth'!S129/('Calc.Mth'!S67*S47) -> 0.71575103 | T34: ='Calc.Mth'!T129/('Calc.Mth'!T67*T47) -> 0.71548706 | ... AI34: ='Calc.Mth'!AI129/('Calc.Mth'!AI67*AI47) -> 0.7038098
B35: Gross Dollar Retention (Monthly Plan) | F35: % | M35: =1-'Calc.Mth'!M37 -> 0.75 | N35: =1-'Calc.Mth'!N37 -> 0.75 | O35: =1-'Calc.Mth'!O37 -> 0.75 | P35: =1-'Calc.Mth'!P37 -> 0.75 | Q35: =1-'Calc.Mth'!Q37 -> 0.75 | R35: =1-'Calc.Mth'!R37 -> 0.75 | S35: =1-'Calc.Mth'!S37 -> 0.75 | T35: =1-'Calc.Mth'!T37 -> 0.75 | ... AI35: =1-'Calc.Mth'!AI37 -> 0.75
B36: Gross Dollar Retention (Annual Plan) | F36: % | M36: =1+'Calc.Mth'!M46/'Calc.Mth'!M43 -> 1 | N36: =1+'Calc.Mth'!N46/'Calc.Mth'!N43 -> 1 | O36: =1+'Calc.Mth'!O46/'Calc.Mth'!O43 -> 1 | P36: =1+'Calc.Mth'!P46/'Calc.Mth'!P43 -> 1 | Q36: =1+'Calc.Mth'!Q46/'Calc.Mth'!Q43 -> 1 | R36: =1+'Calc.Mth'!R46/'Calc.Mth'!R43 -> 1 | S36: =1+'Calc.Mth'!S46/'Calc.Mth'!S43 -> 1 | T36: =1+'Calc.Mth'!T46/'Calc.Mth'!T43 -> 1 | ... AI36: =1+'Calc.Mth'!AI46/'Calc.Mth'!AI43 -> 0.98547121
B38: Headcount | F38: # | L38: ='Calc.Mth'!L98 -> 5 | M38: ='Calc.Mth'!M98 -> 7 | N38: ='Calc.Mth'!N98 -> 10 | O38: ='Calc.Mth'!O98 -> 10 | P38: ='Calc.Mth'!P98 -> 10 | Q38: ='Calc.Mth'!Q98 -> 11 | R38: ='Calc.Mth'!R98 -> 11 | S38: ='Calc.Mth'!S98 -> 11 | ... AI38: ='Calc.Mth'!AI98 -> 20
A40: X | B40: PROFIT & LOSS
B42: Monthly Plan | F42: $k | L42: ='Calc.Mth'!L62 -> 36.8625 | M42: ='Calc.Mth'!M62 -> 86.626875 | N42: ='Calc.Mth'!N62 -> 101.83266 | O42: ='Calc.Mth'!O62 -> 96.32632 | P42: ='Calc.Mth'!P62 -> 81.877372 | Q42: ='Calc.Mth'!Q62 -> 69.595766 | R42: ='Calc.Mth'!R62 -> 59.156401 | S42: ='Calc.Mth'!S62 -> 50.282941 | ... AI42: ='Calc.Mth'!AI62 -> 3.733563
B43: Annual Plan | F43: $k | L43: ='Calc.Mth'!L70 -> 33.790625 | M43: ='Calc.Mth'!M70 -> 87.855625 | N43: ='Calc.Mth'!N70 -> 121.64625 | O43: ='Calc.Mth'!O70 -> 139.89319 | P43: ='Calc.Mth'!P70 -> 149.68571 | Q43: ='Calc.Mth'!Q70 -> 160.16371 | R43: ='Calc.Mth'!R70 -> 171.37517 | S43: ='Calc.Mth'!S70 -> 183.37143 | ... AI43: ='Calc.Mth'!AI70 -> 246.2444
B44: Total Revenue | F44: $k | L44: =SUM(L42:L43) -> 70.653125 | M44: =SUM(M42:M43) -> 174.4825 | N44: =SUM(N42:N43) -> 223.47891 | O44: =SUM(O42:O43) -> 236.21951 | P44: =SUM(P42:P43) -> 231.56308 | Q44: =SUM(Q42:Q43) -> 229.75948 | R44: =SUM(R42:R43) -> 230.53157 | S44: =SUM(S42:S43) -> 233.65437 | ... AI44: =SUM(AI42:AI43) -> 249.97796
B45: COGS | F45: $k | L45: ='Calc.Mth'!L75 -> -26.172375 | M45: ='Calc.Mth'!M75 -> -50.354175 | N45: ='Calc.Mth'!N75 -> -47.110275 | O45: ='Calc.Mth'!O75 -> -40.957924 | P45: ='Calc.Mth'!P75 -> -35.763076 | Q45: ='Calc.Mth'!Q75 -> -35.384408 | R45: ='Calc.Mth'!R75 -> -35.411545 | S45: ='Calc.Mth'!S75 -> -35.808048 | ... AI45: ='Calc.Mth'!AI75 -> -34.718391
B46: Gross Profit | F46: $k | L46: =SUM(L44:L45) -> 44.48075 | M46: =SUM(M44:M45) -> 124.12833 | N46: =SUM(N44:N45) -> 176.36863 | O46: =SUM(O44:O45) -> 195.26158 | P46: =SUM(P44:P45) -> 195.80001 | Q46: =SUM(Q44:Q45) -> 194.37507 | R46: =SUM(R44:R45) -> 195.12003 | S46: =SUM(S44:S45) -> 197.84633 | ... AI46: =SUM(AI44:AI45) -> 215.25957
B47: % margin | F47: % | L47: =L46/L44 -> 0.62956522 | M47: =M46/M44 -> 0.71140845 | N47: =N46/N44 -> 0.78919588 | O47: =O46/O44 -> 0.82661075 | P47: =P46/P44 -> 0.84555796 | Q47: =Q46/Q44 -> 0.8459937 | R47: =R46/R44 -> 0.84639178 | S47: =S46/S44 -> 0.84674779 | ... AI47: =AI46/AI44 -> 0.86111419
B48: Headcount Costs | F48: $k | L48: =-'Calc.Mth'!L97 -> -63.25 | M48: =-'Calc.Mth'!M97 -> -89.125 | N48: =-'Calc.Mth'!N97 -> -132.25 | O48: =-'Calc.Mth'!O97 -> -132.25 | P48: =-'Calc.Mth'!P97 -> -132.25 | Q48: =-'Calc.Mth'!Q97 -> -149.5 | R48: =-'Calc.Mth'!R97 -> -149.5 | S48: =-'Calc.Mth'!S97 -> -149.5 | ... AI48: =-'Calc.Mth'!AI97 -> -310.5
B49: G&A | F49: $k | L49: =-'Calc.Mth'!L126 -> -20 | M49: =-'Calc.Mth'!M126 -> -20 | N49: =-'Calc.Mth'!N126 -> -21.4 | O49: =-'Calc.Mth'!O126 -> -21.4 | P49: =-'Calc.Mth'!P126 -> -21.4 | Q49: =-'Calc.Mth'!Q126 -> -22.898 | R49: =-'Calc.Mth'!R126 -> -22.898 | S49: =-'Calc.Mth'!S126 -> -22.898 | ... AI49: =-'Calc.Mth'!AI126 -> -34.363724
B50: S&M | F50: $k | L50: =-'Calc.Mth'!L128 -> -983 | M50: =-'Calc.Mth'!M128 -> -589.8 | N50: =-'Calc.Mth'!N128 -> -393.2 | O50: =-'Calc.Mth'!O128 -> -138.23438 | P50: =-'Calc.Mth'!P128 -> -132.63742 | Q50: =-'Calc.Mth'!Q128 -> -128.93968 | R50: =-'Calc.Mth'!R128 -> -126.93045 | S50: =-'Calc.Mth'!S128 -> -126.43583 | ... AI50: =-'Calc.Mth'!AI128 -> -202.06016
B51: Facilities Expense | F51: $k | L51: =-'Calc.Mth'!L135 -> -14 | M51: =-'Calc.Mth'!M135 -> -14 | N51: =-'Calc.Mth'!N135 -> -14 | O51: =-'Calc.Mth'!O135 -> -14 | P51: =-'Calc.Mth'!P135 -> -14 | Q51: =-'Calc.Mth'!Q135 -> -14 | R51: =-'Calc.Mth'!R135 -> -14 | S51: =-'Calc.Mth'!S135 -> -14 | ... AI51: =-'Calc.Mth'!AI135 -> -28
B52: Miscellaneous | F52: $k | L52: =-'Calc.Mth'!L137 -> -3.5326562 | M52: =-'Calc.Mth'!M137 -> -8.724125 | N52: =-'Calc.Mth'!N137 -> -11.173945 | O52: =-'Calc.Mth'!O137 -> -11.810975 | P52: =-'Calc.Mth'!P137 -> -11.578154 | Q52: =-'Calc.Mth'!Q137 -> -11.487974 | R52: =-'Calc.Mth'!R137 -> -11.526579 | S52: =-'Calc.Mth'!S137 -> -11.682719 | ... AI52: =-'Calc.Mth'!AI137 -> -12.498898
B53: EBITDA | F53: $k | L53: =SUM(L48:L52,L46) -> -1039.3019 | M53: =SUM(M48:M52,M46) -> -597.5208 | N53: =SUM(N48:N52,N46) -> -395.65531 | O53: =SUM(O48:O52,O46) -> -122.43377 | P53: =SUM(P48:P52,P46) -> -116.06557 | Q53: =SUM(Q48:Q52,Q46) -> -132.45058 | R53: =SUM(R48:R52,R46) -> -129.73501 | S53: =SUM(S48:S52,S46) -> -126.67022 | ... AI53: =SUM(AI48:AI52,AI46) -> -372.16321
...

Sheet Fin.Qtr
B3: ='Calc.Mth'!B3 -> Project Eagle
B4: Summary Financials | Quarterly | G4: Runway | H4: Fundraise | I4: Fund. Date | J4: End. ARR | K4: Deferred Rev.
B5: =Ctrl!$B$5 -> CASE 1: BASE CASE | G5: =Sum!$E$19 -> 16 | H5: =Sum!$E$28 -> 3259.9201 | I5: =Sum!$E$21 -> 45626 | J5: ='Calc.Mth'!$AI$57 -> 2999.7355 | K5: =Fin.Mth!$AI$81 -> 1487.7626 | L5: QUARTERLY | U5: ANNUAL
B7: ='Calc.Mth'!B7 -> Period End | L7: 45382 | M7: =EOMONTH(M8,2) -> 45473 | N7: =EOMONTH(N8,2) -> 45565 | O7: =EOMONTH(O8,2) -> 45657 | P7: =EOMONTH(P8,2) -> 45747 | Q7: =EOMONTH(Q8,2) -> 45838 | R7: =EOMONTH(R8,2) -> 45930 | S7: =EOMONTH(S8,2) -> 46022 | U7: =O7 -> 45657 | V7: =S7 -> 46022
B8: ='Calc.Mth'!B8 -> Period Start | L8: ='Calc.Mth'!L8 -> 45292 | M8: =L7+1 -> 45383 | N8: =M7+1 -> 45474 | O8: =N7+1 -> 45566 | P8: =O7+1 -> 45658 | Q8: =P7+1 -> 45748 | R8: =Q7+1 -> 45839 | S8: =R7+1 -> 45931 | U8: =L8 -> 45292 | V8: =U7+1 -> 45658
B9: ='Calc.Mth'!B9 -> Calendar Year | L9: =YEAR(L7) -> 2024 | M9: =YEAR(M7) -> 2024 | N9: =YEAR(N7) -> 2024 | O9: =YEAR(O7) -> 2024 | P9: =YEAR(P7) -> 2025 | Q9: =YEAR(Q7) -> 2025 | R9: =YEAR(R7) -> 2025 | S9: =YEAR(S7) -> 2025 | U9: =YEAR(U7) -> 2024 | V9: =YEAR(V7) -> 2025
B10: ='Calc.Mth'!B10 -> Period Number | L10: ='Calc.Mth'!L10 -> 1 | M10: ='Calc.Mth'!M10 -> 2 | N10: ='Calc.Mth'!N10 -> 3 | O10: ='Calc.Mth'!O10 -> 4 | P10: ='Calc.Mth'!P10 -> 5 | Q10: ='Calc.Mth'!Q10 -> 6 | R10: ='Calc.Mth'!R10 -> 7 | S10: ='Calc.Mth'!S10 -> 8 | U10: ='Calc.Mth'!U10 -> 10 | V10: ='Calc.Mth'!V10 -> 11
B11: ='Calc.Mth'!B11 -> Days in Period | F11: ='Calc.Mth'!F11 -> Units | H11: ='Calc.Mth'!H11 -> Input I | I11: ='Calc.Mth'!I11 -> Input II | J11: ='Calc.Mth'!J11 -> Input III | K11: ='Calc.Mth'!K11 -> Total / Out | L11: =L7-L8+1 -> 91 | M11: =M7-M8+1 -> 91 | N11: =N7-N8+1 -> 92 | O11: =O7-O8+1 -> 92 | P11: =P7-P8+1 -> 90 | Q11: =Q7-Q8+1 -> 91 | R11: =R7-R8+1 -> 92 | S11: =S7-S8+1 -> 92 | U11: =U7-U8+1 -> 366 | V11: =V7-V8+1 -> 365
A15: X | B15: OPERATING METRICS
B17: # CUSTOMERS
B18: Monthly Plan | F18: # | L18: =SUMIFS(Fin.Mth!$L18:$AI18,Fin.Mth!$L$7:$AI$7,"="&Fin.Qtr!L$7) -> 3471.2188 | M18: =SUMIFS(Fin.Mth!$L18:$AI18,Fin.Mth!$L$7:$AI$7,"="&Fin.Qtr!M$7) -> 2131.7622 | N18: =SUMIFS(Fin.Mth!$L18:$AI18,Fin.Mth!$L$7:$AI$7,"="&Fin.Qtr!N$7) -> 1309.1685 | O18: =SUMIFS(Fin.Mth!$L18:$AI18,Fin.Mth!$L$7:$AI$7,"="&Fin.Qtr!O$7) -> 803.99309 | P18: =SUMIFS(Fin.Mth!$L18:$AI18,Fin.Mth!$L$7:$AI$7,"="&Fin.Qtr!P$7) -> 493.75225 | Q18: =SUMIFS(Fin.Mth!$L18:$AI18,Fin.Mth!$L$7:$AI$7,"="&Fin.Qtr!Q$7) -> 303.2256 | R18: =SUMIFS(Fin.Mth!$L18:$AI18,Fin.Mth!$L$7:$AI$7,"="&Fin.Qtr!R$7) -> 186.21842 | S18: =SUMIFS(Fin.Mth!$L18:$AI18,Fin.Mth!$L$7:$AI$7,"="&Fin.Qtr!S$7) -> 114.36139 | U18: =AVERAGE(L18:O18) -> 1929.0356 | V18: =AVERAGE(P18:S18) -> 274.38942
B19: Annual Plan | F19: # | L19: =SUMIFS(Fin.Mth!$L19:$AI19,Fin.Mth!$L$7:$AI$7,"="&Fin.Qtr!L$7) -> 4915 | M19: =SUMIFS(Fin.Mth!$L19:$AI19,Fin.Mth!$L$7:$AI$7,"="&Fin.Qtr!M$7) -> 6021.0863 | N19: =SUMIFS(Fin.Mth!$L19:$AI19,Fin.Mth!$L$7:$AI$7,"="&Fin.Qtr!N$7) -> 7376.0897 | O19: =SUMIFS(Fin.Mth!$L19:$AI19,Fin.Mth!$L$7:$AI$7,"="&Fin.Qtr!O$7) -> 9036.027 | P19: =SUMIFS(Fin.Mth!$L19:$AI19,Fin.Mth!$L$7:$AI$7,"="&Fin.Qtr!P$7) -> 9188.5143 | Q19: =SUMIFS(Fin.Mth!$L19:$AI19,Fin.Mth!$L$7:$AI$7,"="&Fin.Qtr!Q$7) -> 10842.727 | R19: =SUMIFS(Fin.Mth!$L19:$AI19,Fin.Mth!$L$7:$AI$7,"="&Fin.Qtr!R$7) -> 12776.132 | S19: =SUMIFS(Fin.Mth!$L19:$AI19,Fin.Mth!$L$7:$AI$7,"="&Fin.Qtr!S$7) -> 15030.612 | U19: =AVERAGE(L19:O19) -> 6837.0508 | V19: =AVERAGE(P19:S19) -> 11959.496
B20: TOTAL | F20: # | L20: =SUMIFS(Fin.Mth!$L20:$AI20,Fin.Mth!$L$7:$AI$7,"="&Fin.Qtr!L$7) -> 8386.2188 | M20: =SUMIFS(Fin.Mth!$L20:$AI20,Fin.Mth!$L$7:$AI$7,"="&Fin.Qtr!M$7) -> 8152.8486 | N20: =SUMIFS(Fin.Mth!$L20:$AI20,Fin.Mth!$L$7:$AI$7,"="&Fin.Qtr!N$7) -> 8685.2581 | O20: =SUMIFS(Fin.Mth!$L20:$AI20,Fin.Mth!$L$7:$AI$7,"="&Fin.Qtr!O$7) -> 9840.0201 | P20: =SUMIFS(Fin.Mth!$L20:$AI20,Fin.Mth!$L$7:$AI$7,"="&Fin.Qtr!P$7) -> 9682.2666 | Q20: =SUMIFS(Fin.Mth!$L20:$AI20,Fin.Mth!$L$7:$AI$7,"="&Fin.Qtr!Q$7) -> 11145.953 | R20: =SUMIFS(Fin.Mth!$L20:$AI20,Fin.Mth!$L$7:$AI$7,"="&Fin.Qtr!R$7) -> 12962.35 | S20: =SUMIFS(Fin.Mth!$L20:$AI20,Fin.Mth!$L$7:$AI$7,"="&Fin.Qtr!S$7) -> 15144.973 | U20: =AVERAGE(L20:O20) -> 8766.0864 | V20: =AVERAGE(P20:S20) -> 12233.886
B22: PRICING
B23: Monthly | F23: $k | L23: =AVERAGEIFS(Fin.Mth!$L23:$AI23,Fin.Mth!$L$7:$AI$7,">="&Fin.Qtr!L$8,Fin.Mth!$L$7:$AI$7,"<="&Fin.Qtr!L$7) -> 30 | M23: =AVERAGEIFS(Fin.Mth!$L23:$AI23,Fin.Mth!$L$7:$AI$7,">="&Fin.Qtr!M$8,Fin.Mth!$L$7:$AI$7,"<="&Fin.Qtr!M$7) -> 30 | N23: =AVERAGEIFS(Fin.Mth!$L23:$AI23,Fin.Mth!$L$7:$AI$7,">="&Fin.Qtr!N$8,Fin.Mth!$L$7:$AI$7,"<="&Fin.Qtr!N$7) -> 30 | O23: =AVERAGEIFS(Fin.Mth!$L23:$AI23,Fin.Mth!$L$7:$AI$7,">="&Fin.Qtr!O$8,Fin.Mth!$L$7:$AI$7,"<="&Fin.Qtr!O$7) -> 30 | P23: =AVERAGEIFS(Fin.Mth!$L23:$AI23,Fin.Mth!$L$7:$AI$7,">="&Fin.Qtr!P$8,Fin.Mth!$L$7:$AI$7,"<="&Fin.Qtr!P$7) -> 30 | Q23: =AVERAGEIFS(Fin.Mth!$L23:$AI23,Fin.Mth!$L$7:$AI$7,">="&Fin.Qtr!Q$8,Fin.Mth!$L$7:$AI$7,"<="&Fin.Qtr!Q$7) -> 30 | R23: =AVERAGEIFS(Fin.Mth!$L23:$AI23,Fin.Mth!$L$7:$AI$7,">="&Fin.Qtr!R$8,Fin.Mth!$L$7:$AI$7,"<="&Fin.Qtr!R$7) -> 30 | S23: =AVERAGEIFS(Fin.Mth!$L23:$AI23,Fin.Mth!$L$7:$AI$7,">="&Fin.Qtr!S$8,Fin.Mth!$L$7:$AI$7,"<="&Fin.Qtr!S$7) -> 30 | U23: =AVERAGE(L23:O23) -> 30 | V23: =AVERAGE(P23:S23) -> 30
B24: Annual | F24: $k | L24: =AVERAGEIFS(Fin.Mth!$L24:$AI24,Fin.Mth!$L$7:$AI$7,">="&Fin.Qtr!L$8,Fin.Mth!$L$7:$AI$7,"<="&Fin.Qtr!L$7) -> 330 | M24: =AVERAGEIFS(Fin.Mth!$L24:$AI24,Fin.Mth!$L$7:$AI$7,">="&Fin.Qtr!M$8,Fin.Mth!$L$7:$AI$7,"<="&Fin.Qtr!M$7) -> 330 | N24: =AVERAGEIFS(Fin.Mth!$L24:$AI24,Fin.Mth!$L$7:$AI$7,">="&Fin.Qtr!N$8,Fin.Mth!$L$7:$AI$7,"<="&Fin.Qtr!N$7) -> 330 | O24: =AVERAGEIFS(Fin.Mth!$L24:$AI24,Fin.Mth!$L$7:$AI$7,">="&Fin.Qtr!O$8,Fin.Mth!$L$7:$AI$7,"<="&Fin.Qtr!O$7) -> 330 | P24: =AVERAGEIFS(Fin.Mth!$L24:$AI24,Fin.Mth!$L$7:$AI$7,">="&Fin.Qtr!P$8,Fin.Mth!$L$7:$AI$7,"<="&Fin.Qtr!P$7) -> 330 | Q24: =AVERAGEIFS(Fin.Mth!$L24:$AI24,Fin.Mth!$L$7:$AI$7,">="&Fin.Qtr!Q$8,Fin.Mth!$L$7:$AI$7,"<="&Fin.Qtr!Q$7) -> 330 | R24: =AVERAGEIFS(Fin.Mth!$L24:$AI24,Fin.Mth!$L$7:$AI$7,">="&Fin.Qtr!R$8,Fin.Mth!$L$7:$AI$7,"<="&Fin.Qtr!R$7) -> 330 | S24: =AVERAGEIFS(Fin.Mth!$L24:$AI24,Fin.Mth!$L$7:$AI$7,">="&Fin.Qtr!S$8,Fin.Mth!$L$7:$AI$7,"<="&Fin.Qtr!S$7) -> 330 | U24: =AVERAGE(L24:O24) -> 330 | V24: =AVERAGE(P24:S24) -> 330
B25: TOTAL | F25: $k | L25: =AVERAGEIFS(Fin.Mth!$L25:$AI25,Fin.Mth!$L$7:$AI$7,">="&Fin.Qtr!L$8,Fin.Mth!$L$7:$AI$7,"<="&Fin.Qtr!L$7) -> 21.697049 | M25: =AVERAGEIFS(Fin.Mth!$L25:$AI25,Fin.Mth!$L$7:$AI$7,">="&Fin.Qtr!M$8,Fin.Mth!$L$7:$AI$7,"<="&Fin.Qtr!M$7) -> 28.473223 | N25: =AVERAGEIFS(Fin.Mth!$L25:$AI25,Fin.Mth!$L$7:$AI$7,">="&Fin.Qtr!N$8,Fin.Mth!$L$7:$AI$7,"<="&Fin.Qtr!N$7) -> 27.714799 | O25: =AVERAGEIFS(Fin.Mth!$L25:$AI25,Fin.Mth!$L$7:$AI$7,">="&Fin.Qtr!O$8,Fin.Mth!$L$7:$AI$7,"<="&Fin.Qtr!O$7) -> 27.217225 | P25: =AVERAGEIFS(Fin.Mth!$L25:$AI25,Fin.Mth!$L$7:$AI$7,">="&Fin.Qtr!P$8,Fin.Mth!$L$7:$AI$7,"<="&Fin.Qtr!P$7) -> 22.245689 | Q25: =AVERAGEIFS(Fin.Mth!$L25:$AI25,Fin.Mth!$L$7:$AI$7,">="&Fin.Qtr!Q$8,Fin.Mth!$L$7:$AI$7,"<="&Fin.Qtr!Q$7) -> 17.802969 | R25: =AVERAGEIFS(Fin.Mth!$L25:$AI25,Fin.Mth!$L$7:$AI$7,">="&Fin.Qtr!R$8,Fin.Mth!$L$7:$AI$7,"<="&Fin.Qtr!R$7) -> 17.198682 | S25: =AVERAGEIFS(Fin.Mth!$L25:$AI25,Fin.Mth!$L$7:$AI$7,">="&Fin.Qtr!S$8,Fin.Mth!$L$7:$AI$7,"<="&Fin.Qtr!S$7) -> 16.673421 | U25: =AVERAGE(L25:O25) -> 26.275574 | V25: =AVERAGE(P25:S25) -> 18.48019
B27: REVENUE METRICS
B28: Bookings | F28: $k | L28: =SUMIFS(Fin.Mth!$L28:$AI28,Fin.Mth!$L$7:$AI$7,">="&Fin.Qtr!L$8,Fin.Mth!$L$7:$AI$7,"<="&Fin.Qtr!L$7) -> 1685.077 | M28: =SUMIFS(Fin.Mth!$L28:$AI28,Fin.Mth!$L$7:$AI$7,">="&Fin.Qtr!M$8,Fin.Mth!$L$7:$AI$7,"<="&Fin.Qtr!M$7) -> 710.00898 | N28: =SUMIFS(Fin.Mth!$L28:$AI28,Fin.Mth!$L$7:$AI$7,">="&Fin.Qtr!N$8,Fin.Mth!$L$7:$AI$7,"<="&Fin.Qtr!N$7) -> 584.70451 | O28: =SUMIFS(Fin.Mth!$L28:$AI28,Fin.Mth!$L$7:$AI$7,">="&Fin.Qtr!O$8,Fin.Mth!$L$7:$AI$7,"<="&Fin.Qtr!O$7) -> 623.31876 | P28: =SUMIFS(Fin.Mth!$L28:$AI28,Fin.Mth!$L$7:$AI$7,">="&Fin.Qtr!P$8,Fin.Mth!$L$7:$AI$7,"<="&Fin.Qtr!P$7) -> 670.03803 | Q28: =SUMIFS(Fin.Mth!$L28:$AI28,Fin.Mth!$L$7:$AI$7,">="&Fin.Qtr!Q$8,Fin.Mth!$L$7:$AI$7,"<="&Fin.Qtr!Q$7) -> 693.26005 | R28: =SUMIFS(Fin.Mth!$L28:$AI28,Fin.Mth!$L$7:$AI$7,">="&Fin.Qtr!R$8,Fin.Mth!$L$7:$AI$7,"<="&Fin.Qtr!R$7) -> 794.96787 | S28: =SUMIFS(Fin.Mth!$L28:$AI28,Fin.Mth!$L$7:$AI$7,">="&Fin.Qtr!S$8,Fin.Mth!$L$7:$AI$7,"<="&Fin.Qtr!S$7) -> 924.24868 | U28: =AVERAGE(L28:O28) -> 900.77732 | V28: =AVERAGE(P28:S28) -> 770.62866
B29: Revenue | F29: $k | L29: =SUMIFS(Fin.Mth!$L29:$AI29,Fin.Mth!$L$7:$AI$7,">="&Fin.Qtr!L$8,Fin.Mth!$L$7:$AI$7,"<="&Fin.Qtr!L$7) -> 468.61453 | M29: =SUMIFS(Fin.Mth!$L29:$AI29,Fin.Mth!$L$7:$AI$7,">="&Fin.Qtr!M$8,Fin.Mth!$L$7:$AI$7,"<="&Fin.Qtr!M$7) -> 697.54207 | N29: =SUMIFS(Fin.Mth!$L29:$AI29,Fin.Mth!$L$7:$AI$7,">="&Fin.Qtr!N$8,Fin.Mth!$L$7:$AI$7,"<="&Fin.Qtr!N$7) -> 703.13388 | O29: =SUMIFS(Fin.Mth!$L29:$AI29,Fin.Mth!$L$7:$AI$7,">="&Fin.Qtr!O$8,Fin.Mth!$L$7:$AI$7,"<="&Fin.Qtr!O$7) -> 768.39983 | P29: =SUMIFS(Fin.Mth!$L29:$AI29,Fin.Mth!$L$7:$AI$7,">="&Fin.Qtr!P$8,Fin.Mth!$L$7:$AI$7,"<="&Fin.Qtr!P$7) -> 637.06934 | Q29: =SUMIFS(Fin.Mth!$L29:$AI29,Fin.Mth!$L$7:$AI$7,">="&Fin.Qtr!Q$8,Fin.Mth!$L$7:$AI$7,"<="&Fin.Qtr!Q$7) -> 567.61636 | R29: =SUMIFS(Fin.Mth!$L29:$AI29,Fin.Mth!$L$7:$AI$7,">="&Fin.Qtr!R$8,Fin.Mth!$L$7:$AI$7,"<="&Fin.Qtr!R$7) -> 635.97525 | S29: =SUMIFS(Fin.Mth!$L29:$AI29,Fin.Mth!$L$7:$AI$7,">="&Fin.Qtr!S$8,Fin.Mth!$L$7:$AI$7,"<="&Fin.Qtr!S$7) -> 719.51004 | U29: =AVERAGE(L29:O29) -> 659.42258 | V29: =AVERAGE(P29:S29) -> 640.04275
B30: ARR | F30: $k | L30: =SUMIFS(Fin.Mth!$L30:$AI30,Fin.Mth!$L$7:$AI$7,"="&Fin.Qtr!L$7) -> 2681.7469 | M30: =SUMIFS(Fin.Mth!$L30:$AI30,Fin.Mth!$L$7:$AI$7,"="&Fin.Qtr!M$7) -> 2757.1137 | N30: =SUMIFS(Fin.Mth!$L30:$AI30,Fin.Mth!$L$7:$AI$7,"="&Fin.Qtr!N$7) -> 2867.3752 | O30: =SUMIFS(Fin.Mth!$L30:$AI30,Fin.Mth!$L$7:$AI$7,"="&Fin.Qtr!O$7) -> 3199.3266 | P30: =SUMIFS(Fin.Mth!$L30:$AI30,Fin.Mth!$L$7:$AI$7,"="&Fin.Qtr!P$7) -> 2230.6737 | Q30: =SUMIFS(Fin.Mth!$L30:$AI30,Fin.Mth!$L$7:$AI$7,"="&Fin.Qtr!Q$7) -> 2351.8352 | R30: =SUMIFS(Fin.Mth!$L30:$AI30,Fin.Mth!$L$7:$AI$7,"="&Fin.Qtr!R$7) -> 2646.7928 | S30: =SUMIFS(Fin.Mth!$L30:$AI30,Fin.Mth!$L$7:$AI$7,"="&Fin.Qtr!S$7) -> 2999.7355 | U30: =AVERAGE(L30:O30) -> 2876.3906 | V30: =AVERAGE(P30:S30) -> 2557.2593
B32: SaaS METRICS
B33: CAC Payback (Monthly) | F33: months | M33: =AVERAGEIFS(Fin.Mth!$L33:$AI33,Fin.Mth!$L$7:$AI$7,">="&Fin.Qtr!M$8,Fin.Mth!$L$7:$AI$7,"<="&Fin.Qtr!M$7) -> 7.9432271 | N33: =AVERAGEIFS(Fin.Mth!$L33:$AI33,Fin.Mth!$L$7:$AI$7,">="&Fin.Qtr!N$8,Fin.Mth!$L$7:$AI$7,"<="&Fin.Qtr!N$7) -> 7.8733974 | O33: =AVERAGEIFS(Fin.Mth!$L33:$AI33,Fin.Mth!$L$7:$AI$7,">="&Fin.Qtr!O$8,Fin.Mth!$L$7:$AI$7,"<="&Fin.Qtr!O$7) -> 7.8658393 | P33: =AVERAGEIFS(Fin.Mth!$L33:$AI33,Fin.Mth!$L$7:$AI$7,">="&Fin.Qtr!P$8,Fin.Mth!$L$7:$AI$7,"<="&Fin.Qtr!P$7) -> 7.6802094 | Q33: =AVERAGEIFS(Fin.Mth!$L33:$AI33,Fin.Mth!$L$7:$AI$7,">="&Fin.Qtr!Q$8,Fin.Mth!$L$7:$AI$7,"<="&Fin.Qtr!Q$7) -> 7.7217484 | R33: =AVERAGEIFS(Fin.Mth!$L33:$AI33,Fin.Mth!$L$7:$AI$7,">="&Fin.Qtr!R$8,Fin.Mth!$L$7:$AI$7,"<="&Fin.Qtr!R$7) -> 7.7293888 | S33: =AVERAGEIFS(Fin.Mth!$L33:$AI33,Fin.Mth!$L$7:$AI$7,">="&Fin.Qtr!S$8,Fin.Mth!$L$7:$AI$7,"<="&Fin.Qtr!S$7) -> 7.7386804 | U33: =AVERAGE(L33:O33) -> 7.8941546 | V33: =AVERAGE(P33:S33) -> 7.7175067
B34: CAC Payback (Annual) | F34: months | M34: =AVERAGEIFS(Fin.Mth!$L34:$AI34,Fin.Mth!$L$7:$AI$7,">="&Fin.Qtr!M$8,Fin.Mth!$L$7:$AI$7,"<="&Fin.Qtr!M$7) -> 0.72211156 | N34: =AVERAGEIFS(Fin.Mth!$L34:$AI34,Fin.Mth!$L$7:$AI$7,">="&Fin.Qtr!N$8,Fin.Mth!$L$7:$AI$7,"<="&Fin.Qtr!N$7) -> 0.7157634 | O34: =AVERAGEIFS(Fin.Mth!$L34:$AI34,Fin.Mth!$L$7:$AI$7,">="&Fin.Qtr!O$8,Fin.Mth!$L$7:$AI$7,"<="&Fin.Qtr!O$7) -> 0.7150763 | P34: =AVERAGEIFS(Fin.Mth!$L34:$AI34,Fin.Mth!$L$7:$AI$7,">="&Fin.Qtr!P$8,Fin.Mth!$L$7:$AI$7,"<="&Fin.Qtr!P$7) -> 0.69820085 | Q34: =AVERAGEIFS(Fin.Mth!$L34:$AI34,Fin.Mth!$L$7:$AI$7,">="&Fin.Qtr!Q$8,Fin.Mth!$L$7:$AI$7,"<="&Fin.Qtr!Q$7) -> 0.70197712 | R34: =AVERAGEIFS(Fin.Mth!$L34:$AI34,Fin.Mth!$L$7:$AI$7,">="&Fin.Qtr!R$8,Fin.Mth!$L$7:$AI$7,"<="&Fin.Qtr!R$7) -> 0.70267171 | S34: =AVERAGEIFS(Fin.Mth!$L34:$AI34,Fin.Mth!$L$7:$AI$7,">="&Fin.Qtr!S$8,Fin.Mth!$L$7:$AI$7,"<="&Fin.Qtr!S$7) -> 0.7035164 | U34: =AVERAGE(L34:O34) -> 0.71765042 | V34: =AVERAGE(P34:S34) -> 0.70159152
B35: GDR (Monthly) | F35: % | M35: =AVERAGEIFS(Fin.Mth!$L35:$AI35,Fin.Mth!$L$7:$AI$7,">="&Fin.Qtr!M$8,Fin.Mth!$L$7:$AI$7,"<="&Fin.Qtr!M$7) -> 0.75 | N35: =AVERAGEIFS(Fin.Mth!$L35:$AI35,Fin.Mth!$L$7:$AI$7,">="&Fin.Qtr!N$8,Fin.Mth!$L$7:$AI$7,"<="&Fin.Qtr!N$7) -> 0.75 | O35: =AVERAGEIFS(Fin.Mth!$L35:$AI35,Fin.Mth!$L$7:$AI$7,">="&Fin.Qtr!O$8,Fin.Mth!$L$7:$AI$7,"<="&Fin.Qtr!O$7) -> 0.75 | P35: =AVERAGEIFS(Fin.Mth!$L35:$AI35,Fin.Mth!$L$7:$AI$7,">="&Fin.Qtr!P$8,Fin.Mth!$L$7:$AI$7,"<="&Fin.Qtr!P$7) -> 0.75 | Q35: =AVERAGEIFS(Fin.Mth!$L35:$AI35,Fin.Mth!$L$7:$AI$7,">="&Fin.Qtr!Q$8,Fin.Mth!$L$7:$AI$7,"<="&Fin.Qtr!Q$7) -> 0.75 | R35: =AVERAGEIFS(Fin.Mth!$L35:$AI35,Fin.Mth!$L$7:$AI$7,">="&Fin.Qtr!R$8,Fin.Mth!$L$7:$AI$7,"<="&Fin.Qtr!R$7) -> 0.75 | S35: =AVERAGEIFS(Fin.Mth!$L35:$AI35,Fin.Mth!$L$7:$AI$7,">="&Fin.Qtr!S$8,Fin.Mth!$L$7:$AI$7,"<="&Fin.Qtr!S$7) -> 0.75 | U35: =AVERAGE(L35:O35) -> 0.75 | V35: =AVERAGE(P35:S35) -> 0.75
B36: GDR (Annual) | F36: % | M36: =AVERAGEIFS(Fin.Mth!$L36:$AI36,Fin.Mth!$L$7:$AI$7,">="&Fin.Qtr!M$8,Fin.Mth!$L$7:$AI$7,"<="&Fin.Qtr!M$7) -> 1 | N36: =AVERAGEIFS(Fin.Mth!$L36:$AI36,Fin.Mth!$L$7:$AI$7,">="&Fin.Qtr!N$8,Fin.Mth!$L$7:$AI$7,"<="&Fin.Qtr!N$7) -> 1 | O36: =AVERAGEIFS(Fin.Mth!$L36:$AI36,Fin.Mth!$L$7:$AI$7,">="&Fin.Qtr!O$8,Fin.Mth!$L$7:$AI$7,"<="&Fin.Qtr!O$7) -> 1 | P36: =AVERAGEIFS(Fin.Mth!$L36:$AI36,Fin.Mth!$L$7:$AI$7,">="&Fin.Qtr!P$8,Fin.Mth!$L$7:$AI$7,"<="&Fin.Qtr!P$7) -> 0.93586809 | Q36: =AVERAGEIFS(Fin.Mth!$L36:$AI36,Fin.Mth!$L$7:$AI$7,">="&Fin.Qtr!Q$8,Fin.Mth!$L$7:$AI$7,"<="&Fin.Qtr!Q$7) -> 0.98673092 | R36: =AVERAGEIFS(Fin.Mth!$L36:$AI36,Fin.Mth!$L$7:$AI$7,">="&Fin.Qtr!R$8,Fin.Mth!$L$7:$AI$7,"<="&Fin.Qtr!R$7) -> 0.98621814 | S36: =AVERAGEIFS(Fin.Mth!$L36:$AI36,Fin.Mth!$L$7:$AI$7,">="&Fin.Qtr!S$8,Fin.Mth!$L$7:$AI$7,"<="&Fin.Qtr!S$7) -> 0.98566412 | U36: =AVERAGE(L36:O36) -> 1 | V36: =AVERAGE(P36:S36) -> 0.97362032
B38: Headcount | F38: $k | L38: =AVERAGEIFS(Fin.Mth!$L38:$AI38,Fin.Mth!$L$7:$AI$7,">="&Fin.Qtr!L$8,Fin.Mth!$L$7:$AI$7,"<="&Fin.Qtr!L$7) -> 7.3333333 | M38: =AVERAGEIFS(Fin.Mth!$L38:$AI38,Fin.Mth!$L$7:$AI$7,">="&Fin.Qtr!M$8,Fin.Mth!$L$7:$AI$7,"<="&Fin.Qtr!M$7) -> 10.333333 | N38: =AVERAGEIFS(Fin.Mth!$L38:$AI38,Fin.Mth!$L$7:$AI$7,">="&Fin.Qtr!N$8,Fin.Mth!$L$7:$AI$7,"<="&Fin.Qtr!N$7) -> 11.333333 | O38: =AVERAGEIFS(Fin.Mth!$L38:$AI38,Fin.Mth!$L$7:$AI$7,">="&Fin.Qtr!O$8,Fin.Mth!$L$7:$AI$7,"<="&Fin.Qtr!O$7) -> 13 | P38: =AVERAGEIFS(Fin.Mth!$L38:$AI38,Fin.Mth!$L$7:$AI$7,">="&Fin.Qtr!P$8,Fin.Mth!$L$7:$AI$7,"<="&Fin.Qtr!P$7) -> 13 | Q38: =AVERAGEIFS(Fin.Mth!$L38:$AI38,Fin.Mth!$L$7:$AI$7,">="&Fin.Qtr!Q$8,Fin.Mth!$L$7:$AI$7,"<="&Fin.Qtr!Q$7) -> 15 | R38: =AVERAGEIFS(Fin.Mth!$L38:$AI38,Fin.Mth!$L$7:$AI$7,">="&Fin.Qtr!R$8,Fin.Mth!$L$7:$AI$7,"<="&Fin.Qtr!R$7) -> 16.666667 | S38: =AVERAGEIFS(Fin.Mth!$L38:$AI38,Fin.Mth!$L$7:$AI$7,">="&Fin.Qtr!S$8,Fin.Mth!$L$7:$AI$7,"<="&Fin.Qtr!S$7) -> 18.666667 | U38: =AVERAGE(L38:O38) -> 10.5 | V38: =AVERAGE(P38:S38) -> 15.833333
A40: X | B40: PROFIT & LOSS
B42: =Fin.Mth!B42 -> Monthly Plan | L42: =SUMIFS(Fin.Mth!$L42:$AI42,Fin.Mth!$L$7:$AI$7,">="&Fin.Qtr!L$8,Fin.Mth!$L$7:$AI$7,"<="&Fin.Qtr!L$7) -> 225.32203 | M42: =SUMIFS(Fin.Mth!$L42:$AI42,Fin.Mth!$L$7:$AI$7,">="&Fin.Qtr!M$8,Fin.Mth!$L$7:$AI$7,"<="&Fin.Qtr!M$7) -> 247.79946 | N42: =SUMIFS(Fin.Mth!$L42:$AI42,Fin.Mth!$L$7:$AI$7,">="&Fin.Qtr!N$8,Fin.Mth!$L$7:$AI$7,"<="&Fin.Qtr!N$7) -> 152.17984 | O42: =SUMIFS(Fin.Mth!$L42:$AI42,Fin.Mth!$L$7:$AI$7,">="&Fin.Qtr!O$8,Fin.Mth!$L$7:$AI$7,"<="&Fin.Qtr!O$7) -> 93.457446 | P42: =SUMIFS(Fin.Mth!$L42:$AI42,Fin.Mth!$L$7:$AI$7,">="&Fin.Qtr!P$8,Fin.Mth!$L$7:$AI$7,"<="&Fin.Qtr!P$7) -> 57.394554 | Q42: =SUMIFS(Fin.Mth!$L42:$AI42,Fin.Mth!$L$7:$AI$7,">="&Fin.Qtr!Q$8,Fin.Mth!$L$7:$AI$7,"<="&Fin.Qtr!Q$7) -> 35.24743 | R42: =SUMIFS(Fin.Mth!$L42:$AI42,Fin.Mth!$L$7:$AI$7,">="&Fin.Qtr!R$8,Fin.Mth!$L$7:$AI$7,"<="&Fin.Qtr!R$7) -> 21.646328 | S42: =SUMIFS(Fin.Mth!$L42:$AI42,Fin.Mth!$L$7:$AI$7,">="&Fin.Qtr!S$8,Fin.Mth!$L$7:$AI$7,"<="&Fin.Qtr!S$7) -> 13.293551 | U42: =SUM(L42:O42) -> 718.75878 | V42: =SUM(P42:S42) -> 127.58186
B43: =Fin.Mth!B43 -> Annual Plan | L43: =SUMIFS(Fin.Mth!$L43:$AI43,Fin.Mth!$L$7:$AI$7,">="&Fin.Qtr!L$8,Fin.Mth!$L$7:$AI$7,"<="&Fin.Qtr!L$7) -> 243.2925 | M43: =SUMIFS(Fin.Mth!$L43:$AI43,Fin.Mth!$L$7:$AI$7,">="&Fin.Qtr!M$8,Fin.Mth!$L$7:$AI$7,"<="&Fin.Qtr!M$7) -> 449.74261 | N43: =SUMIFS(Fin.Mth!$L43:$AI43,Fin.Mth!$L$7:$AI$7,">="&Fin.Qtr!N$8,Fin.Mth!$L$7:$AI$7,"<="&Fin.Qtr!N$7) -> 550.95403 | O43: =SUMIFS(Fin.Mth!$L43:$AI43,Fin.Mth!$L$7:$AI$7,">="&Fin.Qtr!O$8,Fin.Mth!$L$7:$AI$7,"<="&Fin.Qtr!O$7) -> 674.94238 | P43: =SUMIFS(Fin.Mth!$L43:$AI43,Fin.Mth!$L$7:$AI$7,">="&Fin.Qtr!P$8,Fin.Mth!$L$7:$AI$7,"<="&Fin.Qtr!P$7) -> 579.67479 | Q43: =SUMIFS(Fin.Mth!$L43:$AI43,Fin.Mth!$L$7:$AI$7,">="&Fin.Qtr!Q$8,Fin.Mth!$L$7:$AI$7,"<="&Fin.Qtr!Q$7) -> 532.36893 | R43: =SUMIFS(Fin.Mth!$L43:$AI43,Fin.Mth!$L$7:$AI$7,">="&Fin.Qtr!R$8,Fin.Mth!$L$7:$AI$7,"<="&Fin.Qtr!R$7) -> 614.32893 | S43: =SUMIFS(Fin.Mth!$L43:$AI43,Fin.Mth!$L$7:$AI$7,">="&Fin.Qtr!S$8,Fin.Mth!$L$7:$AI$7,"<="&Fin.Qtr!S$7) -> 706.21648 | U43: =SUM(L43:O43) -> 1918.9315 | V43: =SUM(P43:S43) -> 2432.5891
B44: =Fin.Mth!B44 -> Total Revenue | F44: $k | L44: =SUMIFS(Fin.Mth!$L44:$AI44,Fin.Mth!$L$7:$AI$7,">="&Fin.Qtr!L$8,Fin.Mth!$L$7:$AI$7,"<="&Fin.Qtr!L$7) -> 468.61453 | M44: =SUMIFS(Fin.Mth!$L44:$AI44,Fin.Mth!$L$7:$AI$7,">="&Fin.Qtr!M$8,Fin.Mth!$L$7:$AI$7,"<="&Fin.Qtr!M$7) -> 697.54207 | N44: =SUMIFS(Fin.Mth!$L44:$AI44,Fin.Mth!$L$7:$AI$7,">="&Fin.Qtr!N$8,Fin.Mth!$L$7:$AI$7,"<="&Fin.Qtr!N$7) -> 703.13388 | O44: =SUMIFS(Fin.Mth!$L44:$AI44,Fin.Mth!$L$7:$AI$7,">="&Fin.Qtr!O$8,Fin.Mth!$L$7:$AI$7,"<="&Fin.Qtr!O$7) -> 768.39983 | P44: =SUMIFS(Fin.Mth!$L44:$AI44,Fin.Mth!$L$7:$AI$7,">="&Fin.Qtr!P$8,Fin.Mth!$L$7:$AI$7,"<="&Fin.Qtr!P$7) -> 637.06934 | Q44: =SUMIFS(Fin.Mth!$L44:$AI44,Fin.Mth!$L$7:$AI$7,">="&Fin.Qtr!Q$8,Fin.Mth!$L$7:$AI$7,"<="&Fin.Qtr!Q$7) -> 567.61636 | R44: =SUMIFS(Fin.Mth!$L44:$AI44,Fin.Mth!$L$7:$AI$7,">="&Fin.Qtr!R$8,Fin.Mth!$L$7:$AI$7,"<="&Fin.Qtr!R$7) -> 635.97525 | S44: =SUMIFS(Fin.Mth!$L44:$AI44,Fin.Mth!$L$7:$AI$7,">="&Fin.Qtr!S$8,Fin.Mth!$L$7:$AI$7,"<="&Fin.Qtr!S$7) -> 719.51004 | U44: =SUM(L44:O44) -> 2637.6903 | V44: =SUM(P44:S44) -> 2560.171
